<robot name="mia_hand_on_ur10" version="1.0">
  <joint name="arm_base_to_arm" type="fixed">
    <origin rpy="0.00000 0.00000 0.00000" xyz="0.00000 0.00000 1.00000"/>
    <parent link="arm_base"/>
    <child link="ur10_base_link"/>
  </joint>
  <joint name="j_index_fle" type="revolute">
    <dynamics damping="0.10000"/>
    <limit lower="-1.40000" upper="1.40000" effort="1.75000" velocity="3.14000"/>
    <origin rpy="-0.59692 1.41555 -0.74981" xyz="0.02631 0.11022 -0.02152"/>
    <parent link="palm"/>
    <child link="index_fle"/>
    <axis xyz="-0.00000 0.00000 1.00000"/>
  </joint>
  <joint name="j_index_sensor" type="fixed">
    <origin rpy="0.00063 -0.00021 0.17208" xyz="-0.00040 0.02424 -0.00018"/>
    <parent link="index_fle"/>
    <child link="index_sensor"/>
  </joint>
  <joint name="j_little_fle" type="revolute">
    <dynamics damping="0.10000"/>
    <limit lower="0" upper="1.39626" effort="1.75000" velocity="3.14000"/>
    <origin rpy="-1.86325 1.36567 -1.51441" xyz="-0.02786 0.10733 -0.02061"/>
    <parent link="palm"/>
    <child link="little_fle"/>
    <axis xyz="-0.00000 0.00000 1.00000"/>
  </joint>
  <joint name="j_middle_sensor" type="fixed">
    <origin rpy="0.00000 0.00000 -0.00000" xyz="0.00044 0.02550 0.00000"/>
    <parent link="middle_fle"/>
    <child link="middle_sensor"/>
  </joint>
  <joint name="j_mrl_fle" type="revolute">
    <dynamics damping="0.10000"/>
    <limit lower="0" upper="1.39626" effort="1.75000" velocity="3.14000"/>
    <origin rpy="-1.57079 1.48353 -1.57079" xyz="0.00515 0.11356 -0.02435"/>
    <parent link="palm"/>
    <child link="middle_fle"/>
    <axis xyz="-0.00000 0.00000 1.00000"/>
  </joint>
  <joint name="j_ring_fle" type="revolute">
    <dynamics damping="0.10000"/>
    <limit lower="0" upper="1.39626" effort="1.75000" velocity="3.14000"/>
    <origin rpy="-1.99078 1.46035 -1.81981" xyz="-0.01225 0.11203 -0.02394"/>
    <parent link="palm"/>
    <child link="ring_fle"/>
    <axis xyz="-0.00000 0.00000 1.00000"/>
  </joint>
  <joint name="j_thumb_fle" type="revolute">
    <dynamics damping="0.10000"/>
    <limit lower="0" upper="1.13450" effort="3.50000" velocity="1.57000"/>
    <origin rpy="-1.57091 0.43822 1.57066" xyz="-0.00003 -0.00001 -0.00899"/>
    <parent link="thumb_sensor"/>
    <child link="thumb_fle"/>
    <axis xyz="-0.00000 0.00000 1.00000"/>
  </joint>
  <joint name="j_thumb_opp" type="revolute">
    <dynamics damping="0.20000"/>
    <limit lower="-0.62800" upper="0.00000" effort="3.50000" velocity="4.00000"/>
    <origin rpy="1.43719 0.36916 0.31859" xyz="0.01307 0.06811 -0.00195"/>
    <parent link="palm"/>
    <child link="thumb_opp"/>
    <axis xyz="-0.00000 0.00000 1.00000"/>
  </joint>
  <joint name="j_thumb_sensor" type="fixed">
    <origin rpy="1.57080 0.00000 -0.00000" xyz="-0.00001 0.00900 0.00000"/>
    <parent link="thumb_opp"/>
    <child link="thumb_sensor"/>
  </joint>
  <joint name="palm_to_flange" type="fixed">
    <origin rpy="0.00000 0.00000 0.00000" xyz="0.00000 0.00000 -0.00000"/>
    <parent link="flange"/>
    <child link="palm"/>
  </joint>
  <joint name="palm_to_hand_ee_link" type="fixed">
    <origin rpy="-0.65000 -0.00000 -0.00000" xyz="0.00000 0.13000 0.03000"/>
    <parent link="palm"/>
    <child link="hand_ee_link"/>
  </joint>
  <joint name="ur10_base_link-base_fixed_joint" type="fixed">
    <origin rpy="0.00000 0.00000 -3.14159" xyz="0.00000 0.00000 0.00000"/>
    <parent link="ur10_base_link"/>
    <child link="ur10_base"/>
  </joint>
  <joint name="ur10_base_link-base_link_inertia" type="fixed">
    <origin rpy="0.00000 0.00000 -3.14159" xyz="0.00000 0.00000 0.00000"/>
    <parent link="ur10_base_link"/>
    <child link="ur10_base_link_inertia"/>
  </joint>
  <joint name="ur10_elbow_joint" type="revolute">
    <limit lower="-3.14159" upper="3.14159" effort="150.00000" velocity="3.14159"/>
    <origin rpy="-0.00000 0.00000 0.00000" xyz="-0.61200 0.00000 0.00000"/>
    <parent link="ur10_upper_arm_link"/>
    <child link="ur10_forearm_link"/>
    <axis xyz="0.00000 0.00000 1.00000"/>
  </joint>
  <joint name="ur10_flange-tool0" type="fixed">
    <origin rpy="1.57080 -0.00000 1.57080" xyz="0.00000 0.00000 0.00000"/>
    <parent link="ur10_flange"/>
    <child link="ur10_tool0"/>
  </joint>
  <joint name="ur10_shoulder_lift_joint" type="revolute">
    <limit lower="-6.28319" upper="6.28319" effort="330.00000" velocity="2.09440"/>
    <origin rpy="1.57080 0.00000 0.00000" xyz="0.00000 0.00000 0.00000"/>
    <parent link="ur10_shoulder_link"/>
    <child link="ur10_upper_arm_link"/>
    <axis xyz="0.00000 0.00000 1.00000"/>
  </joint>
  <joint name="ur10_shoulder_pan_joint" type="revolute">
    <limit lower="-6.28319" upper="6.28319" effort="330.00000" velocity="2.09440"/>
    <origin rpy="0.00000 0.00000 0.00000" xyz="0.00000 0.00000 0.12730"/>
    <parent link="ur10_base_link_inertia"/>
    <child link="ur10_shoulder_link"/>
    <axis xyz="0.00000 0.00000 1.00000"/>
  </joint>
  <joint name="ur10_to_mia" type="fixed">
    <origin rpy="1.57079 0.00000 -1.57080" xyz="-0.00000 -0.00000 0.02200"/>
    <parent link="ur10_tool0"/>
    <child link="flange"/>
  </joint>
  <joint name="ur10_wrist_1_joint" type="revolute">
    <limit lower="-6.28319" upper="6.28319" effort="56.00000" velocity="3.14159"/>
    <origin rpy="-0.00000 0.00000 0.00000" xyz="-0.57230 -0.00000 0.16394"/>
    <parent link="ur10_forearm_link"/>
    <child link="ur10_wrist_1_link"/>
    <axis xyz="0.00000 0.00000 1.00000"/>
  </joint>
  <joint name="ur10_wrist_2_joint" type="revolute">
    <limit lower="-6.28319" upper="6.28319" effort="56.00000" velocity="3.14159"/>
    <origin rpy="1.57080 0.00000 -0.00000" xyz="-0.00000 -0.11570 0.00000"/>
    <parent link="ur10_wrist_1_link"/>
    <child link="ur10_wrist_2_link"/>
    <axis xyz="0.00000 0.00000 1.00000"/>
  </joint>
  <joint name="ur10_wrist_3-flange" type="fixed">
    <origin rpy="1.57080 -1.57080 -3.14159" xyz="0.00000 0.00000 0.00000"/>
    <parent link="ur10_wrist_3_link"/>
    <child link="ur10_flange"/>
  </joint>
  <joint name="ur10_wrist_3_joint" type="revolute">
    <limit lower="-6.28319" upper="6.28319" effort="56.00000" velocity="3.14159"/>
    <origin rpy="-1.57080 0.00000 -0.00000" xyz="-0.00000 0.09220 0.00000"/>
    <parent link="ur10_wrist_2_link"/>
    <child link="ur10_wrist_3_link"/>
    <axis xyz="0.00000 0.00000 1.00000"/>
  </joint>
  <joint name="world_to_robot" type="fixed">
    <origin rpy="0.00000 0.00000 0.00000" xyz="0.00000 0.00000 0.00000"/>
    <parent link="world"/>
    <child link="arm_base"/>
  </joint>
  <link name="arm_base">
    <collision name="arm_base_collision">
      <origin rpy="0.00000 0.00000 0.00000" xyz="0.00000 0.00000 0.50000"/>
      <geometry>
        <box size="0.20000 0.20000 1.00000"/>
      </geometry>
    </collision>
  </link>
  <link name="flange"/>
  <link name="hand_ee_link"/>
  <link name="index_fle">
    <collision name="collision_index_pre_sensor">
      <origin rpy="1.61136 -1.47990 -0.00916" xyz="0.00016 0.02361 0.00151"/>
      <geometry>
        <cylinder radius="0.00713" length="0.01697"/>
      </geometry>
    </collision>
  </link>
  <link name="index_sensor">
    <collision name="collision_index_distal">
      <origin rpy="1.82614 -1.50236 0.11503" xyz="-0.00190 0.04126 0.00138"/>
      <geometry>
        <cylinder radius="0.00796" length="0.03037"/>
      </geometry>
    </collision>
    <collision name="collision_index_post_sensor">
      <origin rpy="1.30726 -1.50236 0.11503" xyz="0.00270 0.01460 0.00128"/>
      <geometry>
        <cylinder radius="0.00713" length="0.01426"/>
      </geometry>
    </collision>
    <collision name="collision_index_tip">
      <origin rpy="-0.71404 -1.36751 1.09491" xyz="-0.01045 0.05966 0.00067"/>
      <geometry>
        <sphere radius="0.00663"/>
      </geometry>
    </collision>
  </link>
  <link name="little_fle">
    <collision name="collision_little_distal">
      <origin rpy="2.01205 -1.54770 0.01482" xyz="-0.00907 0.05236 0.00041"/>
      <geometry>
        <cylinder radius="0.00760" length="0.02993"/>
      </geometry>
    </collision>
    <collision name="collision_little_proximal">
      <origin rpy="1.63933 -1.54051 -0.01082" xyz="-0.00198 0.02730 -0.00004"/>
      <geometry>
        <cylinder radius="0.00783" length="0.03044"/>
      </geometry>
    </collision>
    <collision name="collision_little_tip">
      <origin rpy="2.00573 -1.22295 -1.58026" xyz="-0.01660 0.06473 -0.00036"/>
      <geometry>
        <sphere radius="0.00484"/>
      </geometry>
    </collision>
  </link>
  <link name="middle_fle">
    <collision name="collision_middle_pre_sensor">
      <origin rpy="1.57234 -1.57080 0.00000" xyz="0.00005 0.02010 0.00074"/>
      <geometry>
        <cylinder radius="0.00683" length="0.01782"/>
      </geometry>
    </collision>
  </link>
  <link name="middle_sensor">
    <collision name="collision_middle_distal">
      <origin rpy="2.09122 -1.57080 0.00000" xyz="-0.00865 0.03943 0.00074"/>
      <geometry>
        <cylinder radius="0.00813" length="0.03824"/>
      </geometry>
    </collision>
    <collision name="collision_middle_post_sensor">
      <origin rpy="1.57234 -1.57080 0.00000" xyz="-0.00041 0.01092 0.00074"/>
      <geometry>
        <cylinder radius="0.00683" length="0.01183"/>
      </geometry>
    </collision>
    <collision name="collision_middle_tip">
      <origin rpy="0.52514 -1.57080 0.00000" xyz="-0.02054 0.05640 0.00074"/>
      <geometry>
        <sphere radius="0.00563"/>
      </geometry>
    </collision>
  </link>
  <link name="palm">
    <collision name="collision_hand_distal">
      <origin rpy="-0.26098 0.02436 0.04644" xyz="0.00040 0.09513 -0.02113"/>
      <geometry>
        <box size="0.07264 0.04753 0.03326"/>
      </geometry>
    </collision>
    <collision name="collision_hand_proximal">
      <origin rpy="-0.26526 -0.17953 0.10142" xyz="0.00129 0.04623 -0.00569"/>
      <geometry>
        <box size="0.06241 0.05638 0.02858"/>
      </geometry>
    </collision>
  </link>
  <link name="ring_fle">
    <collision name="collision_ring_distal">
      <origin rpy="-1.04245 -1.56357 -3.12108" xyz="-0.00852 0.06328 0.00022"/>
      <geometry>
        <cylinder radius="0.00760" length="0.02993"/>
      </geometry>
    </collision>
    <collision name="collision_ring_proximal">
      <origin rpy="1.57080 -1.57080 0.00000" xyz="0.00119 0.02893 0.00022"/>
      <geometry>
        <cylinder radius="0.00783" length="0.03683"/>
      </geometry>
    </collision>
    <collision name="collision_ring_tip">
      <origin rpy="2.09440 -1.39626 -1.57080" xyz="-0.01823 0.07664 -0.00019"/>
      <geometry>
        <sphere radius="0.00487"/>
      </geometry>
    </collision>
  </link>
  <link name="thumb_fle">
    <collision name="collision_thumb_distal">
      <origin rpy="1.47056 0.19513 -0.04718" xyz="0.01567 0.04738 0.00140"/>
      <geometry>
        <cylinder radius="0.01169" length="0.05502"/>
      </geometry>
    </collision>
    <collision name="collision_thumb_proximal">
      <origin rpy="1.54384 0.23867 -0.08006" xyz="0.01561 0.03261 0.00006"/>
      <geometry>
        <cylinder radius="0.01271" length="0.05982"/>
      </geometry>
    </collision>
    <collision name="collision_thumb_tip">
      <origin rpy="-0.38283 0.58341 0.64822" xyz="0.01570 0.06996 -0.00076"/>
      <geometry>
        <sphere radius="0.01051"/>
      </geometry>
    </collision>
  </link>
  <link name="thumb_opp"/>
  <link name="thumb_sensor"/>
  <link name="ur10_base"/>
  <link name="ur10_base_link"/>
  <link name="ur10_base_link_inertia">
    <collision name="ur10_base_link_inertia_collision_collision">
      <origin rpy="0.00000 0.00000 -3.14159" xyz="-0.00001 0.00845 0.01900"/>
      <geometry>
        <box size="0.14996 0.16710 0.03800"/>
      </geometry>
    </collision>
    <visual name="ur10_base_link_inertia_collision">
      <origin rpy="0.00000 0.00000 -3.14159" xyz="0.00000 0.00000 0.00000"/>
      <material name="phobos_collision"/>
      <geometry>
        <mesh filename="../meshes/stl/base.stl" scale="1.00000 1.00000 1.00000"/>
      </geometry>
    </visual>
  </link>
  <link name="ur10_flange"/>
  <link name="ur10_forearm_link">
    <collision name="ur10_forearm_link_collision_collision">
      <origin rpy="1.57080 0.00000 -1.57080" xyz="-0.28039 0.00007 0.04820"/>
      <geometry>
        <box size="0.12020 0.13634 0.67816"/>
      </geometry>
    </collision>
    <visual name="ur10_forearm_link_collision">
      <origin rpy="1.57080 0.00000 -1.57080" xyz="-0.00000 -0.00000 0.04904"/>
      <material name="phobos_collision"/>
      <geometry>
        <mesh filename="../meshes/stl/forearm.stl" scale="1.00000 1.00000 1.00000"/>
      </geometry>
    </visual>
  </link>
  <link name="ur10_shoulder_link">
    <collision name="ur10_shoulder_link_collision_collision">
      <origin rpy="0.00000 0.00000 -3.14159" xyz="0.00002 -0.00532 -0.00045"/>
      <geometry>
        <box size="0.15095 0.16137 0.17711"/>
      </geometry>
    </collision>
    <visual name="ur10_shoulder_link_collision">
      <origin rpy="0.00000 0.00000 -3.14159" xyz="0.00000 0.00000 0.00000"/>
      <material name="phobos_collision"/>
      <geometry>
        <mesh filename="../meshes/stl/shoulder.stl" scale="1.00000 1.00000 1.00000"/>
      </geometry>
    </visual>
  </link>
  <link name="ur10_tool0"/>
  <link name="ur10_upper_arm_link">
    <collision name="ur10_upper_arm_link_collision_collision.000">
      <origin rpy="1.57080 0.00000 -1.57080" xyz="-0.29997 0.00010 0.17454"/>
      <geometry>
        <box size="0.15068 0.17726 0.74884"/>
      </geometry>
    </collision>
    <collision name="ur10_upper_arm_link_collision_collision_collision">
      <origin rpy="1.57080 0.00000 -1.57080" xyz="-0.29997 0.00010 0.17454"/>
      <geometry>
        <box size="0.15068 0.17726 0.74884"/>
      </geometry>
    </collision>
    <visual name="ur10_upper_arm_link_collision">
      <origin rpy="1.57080 0.00000 -1.57080" xyz="-0.00000 -0.00000 0.22094"/>
      <material name="phobos_collision"/>
      <geometry>
        <mesh filename="../meshes/stl/upperarm.stl" scale="1.00000 1.00000 1.00000"/>
      </geometry>
    </visual>
    <visual name="ur10_upper_arm_link_collision_collision">
      <origin rpy="1.57080 0.00000 -1.57080" xyz="-0.29997 0.00010 0.17454"/>
      <material name="phobos_collision"/>
      <geometry>
        <box size="0.15068 0.17726 0.74884"/>
      </geometry>
    </visual>
  </link>
  <link name="ur10_wrist_1_link">
    <collision name="ur10_wrist_1_link_collision_collision">
      <origin rpy="1.57080 0.00000 -0.00000" xyz="-0.00020 -0.00259 -0.00398"/>
      <geometry>
        <box size="0.09102 0.10007 0.11882"/>
      </geometry>
    </collision>
    <visual name="ur10_wrist_1_link_collision">
      <origin rpy="1.57080 0.00000 0.00000" xyz="0.00000 0.00000 -0.11490"/>
      <material name="phobos_collision"/>
      <geometry>
        <mesh filename="../meshes/stl/wrist1.stl" scale="1.00000 1.00000 1.00000"/>
      </geometry>
    </visual>
  </link>
  <link name="ur10_wrist_2_link">
    <collision name="ur10_wrist_2_link_collision_collision">
      <origin rpy="0.00000 -0.00000 -0.00000" xyz="0.00005 0.00216 -0.00376"/>
      <geometry>
        <box size="0.09126 0.11887 0.10009"/>
      </geometry>
    </collision>
    <visual name="ur10_wrist_2_link_collision">
      <origin rpy="-0.00000 0.00000 0.00000" xyz="-0.00000 -0.00000 -0.11580"/>
      <material name="phobos_collision"/>
      <geometry>
        <mesh filename="../meshes/stl/wrist2.stl" scale="1.00000 1.00000 1.00000"/>
      </geometry>
    </visual>
  </link>
  <link name="ur10_wrist_3_link">
    <collision name="ur10_wrist_3_link_collision_collision">
      <origin rpy="1.57080 0.00000 -0.00000" xyz="0.00000 -0.00096 -0.01536"/>
      <geometry>
        <box size="0.08993 0.03050 0.09007"/>
      </geometry>
    </collision>
    <visual name="ur10_wrist_3_link_collision">
      <origin rpy="1.57080 -0.00000 0.00000" xyz="0.00000 0.00000 -0.09220"/>
      <material name="phobos_collision"/>
      <geometry>
        <mesh filename="../meshes/stl/wrist3.stl" scale="1.00000 1.00000 1.00000"/>
      </geometry>
    </visual>
  </link>
  <link name="world"/>
  <material name="phobos_collision">
    <color rgba="0.80000 0.49804 0.00000 0.20000"/>
  </material>
</robot>