<?xml version="1.0"?>
<!-- created with Phobos 1.0.1 "Capricious Choutengan" -->
  <robot name="NaoH25V40">

    <link name="CameraBottom_frame">
    </link>

    <link name="CameraBottom_optical_frame">
    </link>

    <link name="CameraTop_frame">
    </link>

    <link name="CameraTop_optical_frame">
    </link>

    <link name="ChestButton_frame">
    </link>

    <link name="Head">
      <inertial>
        <origin xyz="-0.00112 0 0.05258" rpy="0 0 0"/>
        <mass value="0.60533"/>
        <inertia ixx="0.00096" ixy="0" ixz="0" iyy="0.00082" iyz="-3e-05" izz="0.00098"/>
      </inertial>
      <visual name="visual_0_Head">
        <origin xyz="0 0 0" rpy="0 0 0"/>
        <geometry>
          <mesh filename="../meshes/dae/Head.dae" scale="0.1 0.1 0.1"/>
        </geometry>
        <material name="HeadPitchUV"/>
      </visual>
      <collision name="collision_0_Head">
        <origin xyz="0 0 0" rpy="0 0 0"/>
        <geometry>
          <cylinder radius="0.05968" length="0.11439"/>
        </geometry>
      </collision>
    </link>

    <link name="HeadTouchFront_frame">
    </link>

    <link name="HeadTouchMiddle_frame">
    </link>

    <link name="HeadTouchRear_frame">
    </link>

    <link name="ImuTorsoAccelerometer_frame">
    </link>

    <link name="ImuTorsoGyrometer_frame">
    </link>

    <link name="LAnklePitch">
      <inertial>
        <origin xyz="0.00045 0.00029 0.00685" rpy="0 0 0"/>
        <mass value="0.13416"/>
        <inertia ixx="3e-05" ixy="0" ixz="0" iyy="7e-05" iyz="0" izz="5e-05"/>
      </inertial>
      <visual name="visual_0_LAnklePitch">
        <origin xyz="0 0 0" rpy="0 0 0"/>
        <geometry>
          <mesh filename="../meshes/dae/LAnkle.dae" scale="0.1 0.1 0.1"/>
        </geometry>
        <material name="RanklePitchUV"/>
      </visual>
      <collision name="collision_0_LAnklePitch">
        <origin xyz="0 0 0" rpy="0 0 0"/>
        <geometry>
          <box size="0.07146 0.03136 0.06369"/>
        </geometry>
      </collision>
    </link>

    <link name="LBicep">
      <inertial>
        <origin xyz="0.02455 0.00563 0.0033" rpy="0 0 0"/>
        <mass value="0.15777"/>
        <inertia ixx="9e-05" ixy="-3e-05" ixz="0" iyy="0.00027" iyz="0" izz="0.00024"/>
      </inertial>
      <visual name="visual_0_LBicep">
        <origin xyz="0 0 0" rpy="0 0 0"/>
        <geometry>
          <mesh filename="../meshes/dae/LBiceps.dae" scale="0.1 0.1 0.1"/>
        </geometry>
        <material name="LShoulderRollUV"/>
      </visual>
      <collision name="collision_0_LBicep">
        <origin xyz="0 0 0" rpy="0 0 0"/>
        <geometry>
          <box size="0.16906 0.06238 0.08158"/>
        </geometry>
      </collision>
    </link>

    <link name="LElbow">
      <inertial>
        <origin xyz="-0.02744 0 -0.00014" rpy="0 0 0"/>
        <mass value="0.06483"/>
        <inertia ixx="2e-05" ixy="0" ixz="0" iyy="6e-05" iyz="0" izz="6e-05"/>
      </inertial>
    </link>

    <link name="LFinger11_link">
      <inertial>
        <origin xyz="0 0 0" rpy="0 0 0"/>
        <mass value="1e-05"/>
        <inertia ixx="2e-05" ixy="0" ixz="0" iyy="2e-05" iyz="0" izz="2e-05"/>
      </inertial>
      <visual name="visual_0_LFinger11_link">
        <origin xyz="0 0 0" rpy="0 0 0"/>
        <geometry>
          <mesh filename="../meshes/dae/LPhalax_1.dae" scale="0.1 0.1 0.1"/>
        </geometry>
        <material name="LFinger11UV"/>
      </visual>
      <collision name="collision_0_LFinger11_link">
        <origin xyz="0 0 0" rpy="0 0 0"/>
        <geometry>
          <cylinder radius="0.00977" length="0.01232"/>
        </geometry>
      </collision>
    </link>

    <link name="LFinger12_link">
      <inertial>
        <origin xyz="0 0 0" rpy="0 0 0"/>
        <mass value="1e-05"/>
        <inertia ixx="2e-05" ixy="0" ixz="0" iyy="2e-05" iyz="0" izz="2e-05"/>
      </inertial>
      <visual name="visual_0_LFinger12_link">
        <origin xyz="0 0 0" rpy="0 0 0"/>
        <geometry>
          <mesh filename="../meshes/dae/LPhalax_2.dae" scale="0.1 0.1 0.1"/>
        </geometry>
        <material name="LFinger12UV"/>
      </visual>
      <collision name="collision_0_LFinger12_link">
        <origin xyz="0 0 0" rpy="0 0 0"/>
        <geometry>
          <cylinder radius="0.00977" length="0.01232"/>
        </geometry>
      </collision>
    </link>

    <link name="LFinger13_link">
      <inertial>
        <origin xyz="0 0 0" rpy="0 0 0"/>
        <mass value="1e-05"/>
        <inertia ixx="2e-05" ixy="0" ixz="0" iyy="2e-05" iyz="0" izz="2e-05"/>
      </inertial>
      <visual name="visual_0_LFinger13_link">
        <origin xyz="0 0 0" rpy="0 0 0"/>
        <geometry>
          <mesh filename="../meshes/dae/LPhalax_3.dae" scale="0.1 0.1 0.1"/>
        </geometry>
        <material name="Lfindger13UV"/>
      </visual>
      <collision name="collision_0_LFinger13_link">
        <origin xyz="0 0 0" rpy="0 0 0"/>
        <geometry>
          <cylinder radius="0.00986" length="0.0112"/>
        </geometry>
      </collision>
    </link>

    <link name="LFinger21_link">
      <inertial>
        <origin xyz="0 0 0" rpy="0 0 0"/>
        <mass value="1e-05"/>
        <inertia ixx="2e-05" ixy="0" ixz="0" iyy="2e-05" iyz="0" izz="2e-05"/>
      </inertial>
      <visual name="visual_0_LFinger21_link">
        <origin xyz="0 0 0" rpy="0 0 0"/>
        <geometry>
          <mesh filename="../meshes/dae/LPhalax_4.dae" scale="0.1 0.1 0.1"/>
        </geometry>
        <material name="LFinger21UV"/>
      </visual>
      <collision name="collision_0_LFinger21_link">
        <origin xyz="0 0 0" rpy="0 0 0"/>
        <geometry>
          <cylinder radius="0.00977" length="0.01211"/>
        </geometry>
      </collision>
    </link>

    <link name="LFinger22_link">
      <inertial>
        <origin xyz="0 0 0" rpy="0 0 0"/>
        <mass value="1e-05"/>
        <inertia ixx="2e-05" ixy="0" ixz="0" iyy="2e-05" iyz="0" izz="2e-05"/>
      </inertial>
      <visual name="visual_0_LFinger22_link">
        <origin xyz="0 0 0" rpy="0 0 0"/>
        <geometry>
          <mesh filename="../meshes/dae/LPhalax_5.dae" scale="0.1 0.1 0.1"/>
        </geometry>
        <material name="LFinger22UV"/>
      </visual>
      <collision name="collision_0_LFinger22_link">
        <origin xyz="0 0 0" rpy="0 0 0"/>
        <geometry>
          <cylinder radius="0.00977" length="0.01211"/>
        </geometry>
      </collision>
    </link>

    <link name="LFinger23_link">
      <inertial>
        <origin xyz="0 0 0" rpy="0 0 0"/>
        <mass value="1e-05"/>
        <inertia ixx="2e-05" ixy="0" ixz="0" iyy="2e-05" iyz="0" izz="2e-05"/>
      </inertial>
      <visual name="visual_0_LFinger23_link">
        <origin xyz="0 0 0" rpy="0 0 0"/>
        <geometry>
          <mesh filename="../meshes/dae/LPhalax_6.dae" scale="0.1 0.1 0.1"/>
        </geometry>
        <material name="LFinger23UV"/>
      </visual>
      <collision name="collision_0_LFinger23_link">
        <origin xyz="0 0 0" rpy="0 0 0"/>
        <geometry>
          <cylinder radius="0.00986" length="0.01069"/>
        </geometry>
      </collision>
    </link>

    <link name="LFootBumperLeft_frame">
    </link>

    <link name="LFootBumperRight_frame">
    </link>

    <link name="LForeArm">
      <inertial>
        <origin xyz="0.02556 0.00281 0.00076" rpy="0 0 0"/>
        <mass value="0.07761"/>
        <inertia ixx="2e-05" ixy="0" ixz="0" iyy="4e-05" iyz="0" izz="4e-05"/>
      </inertial>
      <visual name="visual_0_LForeArm">
        <origin xyz="0 0 0" rpy="0 0 0"/>
        <geometry>
          <mesh filename="../meshes/dae/LForeArm.dae" scale="0.1 0.1 0.1"/>
        </geometry>
        <material name="LElbowRollUV"/>
      </visual>
      <collision name="collision_0_LForeArm">
        <origin xyz="0 0 0" rpy="0 0 0"/>
        <geometry>
          <box size="0.07212 0.04968 0.05141"/>
        </geometry>
      </collision>
    </link>

    <link name="LFsrFL_frame">
      <inertial>
        <origin xyz="0 0 0" rpy="0 0 0"/>
        <mass value="1e-05"/>
        <inertia ixx="2e-05" ixy="0" ixz="0" iyy="2e-05" iyz="0" izz="2e-05"/>
      </inertial>
      <collision name="collision_0_LFsrFL_frame">
        <origin xyz="0 0 0" rpy="0 0 0"/>
        <geometry>
          <box size="0.01 0.01 0.005"/>
        </geometry>
      </collision>
    </link>

    <link name="LFsrFR_frame">
      <inertial>
        <origin xyz="0 0 0" rpy="0 0 0"/>
        <mass value="1e-05"/>
        <inertia ixx="2e-05" ixy="0" ixz="0" iyy="2e-05" iyz="0" izz="2e-05"/>
      </inertial>
      <collision name="collision_0_LFsrFR_frame">
        <origin xyz="0 0 0" rpy="0 0 0"/>
        <geometry>
          <box size="0.01 0.01 0.005"/>
        </geometry>
      </collision>
    </link>

    <link name="LFsrRL_frame">
      <inertial>
        <origin xyz="0 0 0" rpy="0 0 0"/>
        <mass value="1e-05"/>
        <inertia ixx="2e-05" ixy="0" ixz="0" iyy="2e-05" iyz="0" izz="2e-05"/>
      </inertial>
      <collision name="collision_0_LFsrRL_frame">
        <origin xyz="0 0 0" rpy="0 0 0"/>
        <geometry>
          <box size="0.01 0.01 0.005"/>
        </geometry>
      </collision>
    </link>

    <link name="LFsrRR_frame">
      <inertial>
        <origin xyz="0 0 0" rpy="0 0 0"/>
        <mass value="1e-05"/>
        <inertia ixx="2e-05" ixy="0" ixz="0" iyy="2e-05" iyz="0" izz="2e-05"/>
      </inertial>
      <collision name="collision_0_LFsrRR_frame">
        <origin xyz="0 0 0" rpy="0 0 0"/>
        <geometry>
          <box size="0.01 0.01 0.005"/>
        </geometry>
      </collision>
    </link>

    <link name="LHandTouchBack_frame">
    </link>

    <link name="LHandTouchLeft_frame">
    </link>

    <link name="LHandTouchRight_frame">
    </link>

    <link name="LHip">
      <inertial>
        <origin xyz="-0.01549 0.00029 -0.00515" rpy="0 0 0"/>
        <mass value="0.13053"/>
        <inertia ixx="2e-05" ixy="0" ixz="0" iyy="6e-05" iyz="0" izz="6e-05"/>
      </inertial>
      <visual name="visual_0_LHip">
        <origin xyz="0 0 0" rpy="0 0 0"/>
        <geometry>
          <mesh filename="../meshes/dae/LUpperThigh.dae" scale="0.1 0.1 0.1"/>
        </geometry>
        <material name="LHipRollUV"/>
      </visual>
      <collision name="collision_0_LHip">
        <origin xyz="0 0 0" rpy="0 0 0"/>
        <geometry>
          <box size="0.06259 0.03403 0.05367"/>
        </geometry>
      </collision>
    </link>

    <link name="LInfraRed_frame">
    </link>

    <link name="LPelvis">
      <inertial>
        <origin xyz="-0.00781 -0.01114 0.02661" rpy="0 0 0"/>
        <mass value="0.06981"/>
        <inertia ixx="2e-05" ixy="0" ixz="0" iyy="5e-05" iyz="0" izz="5e-05"/>
      </inertial>
      <visual name="visual_0_LPelvis">
        <origin xyz="0 0 0" rpy="0 0 0"/>
        <geometry>
          <mesh filename="../meshes/dae/LHip.dae" scale="0.1 0.1 0.1"/>
        </geometry>
        <material name="LHipYawPitchUV"/>
      </visual>
      <collision name="collision_0_LPelvis">
        <origin xyz="0 0 0" rpy="0 0 0"/>
        <geometry>
          <cylinder radius="0.0414" length="0.05852"/>
        </geometry>
      </collision>
    </link>

    <link name="LShoulder">
      <inertial>
        <origin xyz="-0.00165 -0.02663 0.00014" rpy="0 0 0"/>
        <mass value="0.07504"/>
        <inertia ixx="6e-05" ixy="0" ixz="0" iyy="2e-05" iyz="0" izz="6e-05"/>
      </inertial>
      <visual name="visual_0_LShoulder">
        <origin xyz="0 0 0" rpy="0 0 0"/>
        <geometry>
          <mesh filename="../meshes/dae/LShoulderPadMobile.dae" scale="0.1 0.1 0.1"/>
        </geometry>
        <material name="NaoMat_MainSkin.011"/>
      </visual>
      <collision name="collision_0_LShoulder">
        <origin xyz="0 0 0" rpy="0 0 0"/>
        <geometry>
          <cylinder radius="0.034" length="0.06628"/>
        </geometry>
      </collision>
    </link>

    <link name="LSonar_frame">
    </link>

    <link name="LThigh">
      <inertial>
        <origin xyz="0.00138 0.00221 -0.05373" rpy="0 0 0"/>
        <mass value="0.38968"/>
        <inertia ixx="0.00051" ixy="0" ixz="6e-05" iyy="0.00047" iyz="0" izz="0.0003"/>
      </inertial>
      <visual name="visual_0_LThigh">
        <origin xyz="0 0 0" rpy="0 0 0"/>
        <geometry>
          <mesh filename="../meshes/dae/LThigh.dae" scale="0.1 0.1 0.1"/>
        </geometry>
        <material name="LHipPitchUV"/>
      </visual>
      <collision name="collision_0_LThigh">
        <origin xyz="0 0 0" rpy="0 0 0"/>
        <geometry>
          <cylinder radius="0.0481" length="0.14907"/>
        </geometry>
      </collision>
    </link>

    <link name="LThumb1_link">
      <inertial>
        <origin xyz="0 0 0" rpy="0 0 0"/>
        <mass value="1e-05"/>
        <inertia ixx="2e-05" ixy="0" ixz="0" iyy="2e-05" iyz="0" izz="2e-05"/>
      </inertial>
      <visual name="visual_0_LThumb1_link">
        <origin xyz="0 0 0" rpy="0 0 0"/>
        <geometry>
          <mesh filename="../meshes/dae/LPhalax_7.dae" scale="0.1 0.1 0.1"/>
        </geometry>
        <material name="LThumb1UV"/>
      </visual>
      <collision name="collision_0_LThumb1_link">
        <origin xyz="0 0 0" rpy="0 0 0"/>
        <geometry>
          <cylinder radius="0.00675" length="0.02155"/>
        </geometry>
      </collision>
    </link>

    <link name="LThumb2_link">
      <inertial>
        <origin xyz="0 0 0" rpy="0 0 0"/>
        <mass value="1e-05"/>
        <inertia ixx="2e-05" ixy="0" ixz="0" iyy="2e-05" iyz="0" izz="2e-05"/>
      </inertial>
      <visual name="visual_0_LThumb2_link">
        <origin xyz="0 0 0" rpy="0 0 0"/>
        <geometry>
          <mesh filename="../meshes/dae/LPhalax_8.dae" scale="0.1 0.1 0.1"/>
        </geometry>
        <material name="LThumb2UV"/>
      </visual>
      <collision name="collision_0_LThumb2_link">
        <origin xyz="0 0 0" rpy="0 0 0"/>
        <geometry>
          <cylinder radius="0.0071" length="0.02066"/>
        </geometry>
      </collision>
    </link>

    <link name="LTibia">
      <inertial>
        <origin xyz="0.00453 0.00225 -0.04936" rpy="0 0 0"/>
        <mass value="0.29142"/>
        <inertia ixx="0.00047" ixy="0" ixz="-3e-05" iyy="0.00041" iyz="0" izz="0.00019"/>
      </inertial>
      <visual name="visual_0_LTibia">
        <origin xyz="0 0 0" rpy="0 0 0"/>
        <geometry>
          <mesh filename="../meshes/dae/LShinebone.dae" scale="0.1 0.1 0.1"/>
        </geometry>
        <material name="LKneePitchUV"/>
      </visual>
      <collision name="collision_0_LTibia">
        <origin xyz="0 0 0" rpy="0 0 0"/>
        <geometry>
          <cylinder radius="0.0456" length="0.1512"/>
        </geometry>
      </collision>
    </link>

    <link name="MicroFrontCenter_frame">
    </link>

    <link name="MicroRearCenter_frame">
    </link>

    <link name="MicroSurroundLeft_frame">
    </link>

    <link name="MicroSurroundRight_frame">
    </link>

    <link name="Neck">
      <inertial>
        <origin xyz="0 0 -0.02742" rpy="0 0 0"/>
        <mass value="0.06442"/>
        <inertia ixx="6e-05" ixy="0" ixz="0" iyy="6e-05" iyz="0" izz="2e-05"/>
      </inertial>
      <visual name="visual_0_Neck">
        <origin xyz="0 0 0" rpy="0 0 0"/>
        <geometry>
          <mesh filename="../meshes/dae/Neck.dae" scale="0.1 0.1 0.1"/>
        </geometry>
        <material name="HeadYawuv"/>
      </visual>
      <collision name="collision_0_Neck">
        <origin xyz="0 0 0" rpy="0 0 0"/>
        <geometry>
          <box size="0.0252 0.0252 0.0252"/>
        </geometry>
      </collision>
    </link>

    <link name="RAnklePitch">
      <inertial>
        <origin xyz="0.00045 -0.00029 0.00685" rpy="0 0 0"/>
        <mass value="0.13416"/>
        <inertia ixx="3e-05" ixy="0" ixz="0" iyy="7e-05" iyz="0" izz="5e-05"/>
      </inertial>
      <visual name="visual_0_RAnklePitch">
        <origin xyz="0 0 0" rpy="0 0 0"/>
        <geometry>
          <mesh filename="../meshes/dae/RAnkle.dae" scale="0.1 0.1 0.1"/>
        </geometry>
        <material name="RAnklePitchUV"/>
      </visual>
      <collision name="collision_0_RAnklePitch">
        <origin xyz="0 0 0" rpy="0 0 0"/>
        <geometry>
          <box size="0.07404 0.03136 0.06433"/>
        </geometry>
      </collision>
    </link>

    <link name="RBicep">
      <inertial>
        <origin xyz="0.02455 -0.00563 0.0033" rpy="0 0 0"/>
        <mass value="0.15777"/>
        <inertia ixx="0.0001" ixy="5e-05" ixz="0" iyy="0.00027" iyz="0" izz="0.00025"/>
      </inertial>
      <visual name="visual_0_RBicep">
        <origin xyz="0 0 0" rpy="0 0 0"/>
        <geometry>
          <mesh filename="../meshes/dae/RBiceps.dae" scale="0.1 0.1 0.1"/>
        </geometry>
        <material name="RshoulderRollUV"/>
      </visual>
      <collision name="collision_0_RBicep">
        <origin xyz="0 0 0" rpy="0 0 0"/>
        <geometry>
          <box size="0.17183 0.06085 0.08297"/>
        </geometry>
      </collision>
    </link>

    <link name="RElbow">
      <inertial>
        <origin xyz="-0.02744 0 -0.00014" rpy="0 0 0"/>
        <mass value="0.06483"/>
        <inertia ixx="2e-05" ixy="0" ixz="0" iyy="6e-05" iyz="0" izz="6e-05"/>
      </inertial>
    </link>

    <link name="RFinger11_link">
      <inertial>
        <origin xyz="0 0 0" rpy="0 0 0"/>
        <mass value="1e-05"/>
        <inertia ixx="2e-05" ixy="0" ixz="0" iyy="2e-05" iyz="0" izz="2e-05"/>
      </inertial>
      <visual name="visual_0_RFinger11_link">
        <origin xyz="0 0 0" rpy="0 0 0"/>
        <geometry>
          <mesh filename="../meshes/dae/RPhalax_1.dae" scale="0.1 0.1 0.1"/>
        </geometry>
        <material name="RFinger11UV"/>
      </visual>
      <collision name="collision_0_RFinger11_link">
        <origin xyz="0 0 0" rpy="0 0 0"/>
        <geometry>
          <cylinder radius="0.00977" length="0.01232"/>
        </geometry>
      </collision>
    </link>

    <link name="RFinger12_link">
      <inertial>
        <origin xyz="0 0 0" rpy="0 0 0"/>
        <mass value="1e-05"/>
        <inertia ixx="2e-05" ixy="0" ixz="0" iyy="2e-05" iyz="0" izz="2e-05"/>
      </inertial>
      <visual name="visual_0_RFinger12_link">
        <origin xyz="0 0 0" rpy="0 0 0"/>
        <geometry>
          <mesh filename="../meshes/dae/RPhalax_2.dae" scale="0.1 0.1 0.1"/>
        </geometry>
        <material name="RFinger12UV"/>
      </visual>
      <collision name="collision_0_RFinger12_link">
        <origin xyz="0 0 0" rpy="0 0 0"/>
        <geometry>
          <cylinder radius="0.00977" length="0.01264"/>
        </geometry>
      </collision>
    </link>

    <link name="RFinger13_link">
      <inertial>
        <origin xyz="0 0 0" rpy="0 0 0"/>
        <mass value="1e-05"/>
        <inertia ixx="2e-05" ixy="0" ixz="0" iyy="2e-05" iyz="0" izz="2e-05"/>
      </inertial>
      <visual name="visual_0_RFinger13_link">
        <origin xyz="0 0 0" rpy="0 0 0"/>
        <geometry>
          <mesh filename="../meshes/dae/RPhalax_3.dae" scale="0.1 0.1 0.1"/>
        </geometry>
        <material name="RFinger13UV"/>
      </visual>
      <collision name="collision_0_RFinger13_link">
        <origin xyz="0 0 0" rpy="0 0 0"/>
        <geometry>
          <cylinder radius="0.00986" length="0.0112"/>
        </geometry>
      </collision>
    </link>

    <link name="RFinger21_link">
      <inertial>
        <origin xyz="0 0 0" rpy="0 0 0"/>
        <mass value="1e-05"/>
        <inertia ixx="2e-05" ixy="0" ixz="0" iyy="2e-05" iyz="0" izz="2e-05"/>
      </inertial>
      <visual name="visual_0_RFinger21_link">
        <origin xyz="0 0 0" rpy="0 0 0"/>
        <geometry>
          <mesh filename="../meshes/dae/RPhalax_4.dae" scale="0.1 0.1 0.1"/>
        </geometry>
        <material name="RFinger21UV"/>
      </visual>
      <collision name="collision_0_RFinger21_link">
        <origin xyz="0 0 0" rpy="0 0 0"/>
        <geometry>
          <cylinder radius="0.00977" length="0.01211"/>
        </geometry>
      </collision>
    </link>

    <link name="RFinger22_link">
      <inertial>
        <origin xyz="0 0 0" rpy="0 0 0"/>
        <mass value="1e-05"/>
        <inertia ixx="2e-05" ixy="0" ixz="0" iyy="2e-05" iyz="0" izz="2e-05"/>
      </inertial>
      <visual name="visual_0_RFinger22_link">
        <origin xyz="0 0 0" rpy="0 0 0"/>
        <geometry>
          <mesh filename="../meshes/dae/RPhalax_5.dae" scale="0.1 0.1 0.1"/>
        </geometry>
        <material name="RFinger22UV"/>
      </visual>
      <collision name="collision_0_RFinger22_link">
        <origin xyz="0 0 0" rpy="0 0 0"/>
        <geometry>
          <cylinder radius="0.00977" length="0.01211"/>
        </geometry>
      </collision>
    </link>

    <link name="RFinger23_link">
      <inertial>
        <origin xyz="0 0 0" rpy="0 0 0"/>
        <mass value="1e-05"/>
        <inertia ixx="2e-05" ixy="0" ixz="0" iyy="2e-05" iyz="0" izz="2e-05"/>
      </inertial>
      <visual name="visual_0_RFinger23_link">
        <origin xyz="0 0 0" rpy="0 0 0"/>
        <geometry>
          <mesh filename="../meshes/dae/RPhalax_6.dae" scale="0.1 0.1 0.1"/>
        </geometry>
        <material name="RFinger23UV"/>
      </visual>
      <collision name="collision_0_RFinger23_link">
        <origin xyz="0 0 0" rpy="0 0 0"/>
        <geometry>
          <cylinder radius="0.00986" length="0.01118"/>
        </geometry>
      </collision>
    </link>

    <link name="RFootBumperLeft_frame">
    </link>

    <link name="RFootBumperRight_frame">
    </link>

    <link name="RForeArm">
      <inertial>
        <origin xyz="0.02556 -0.00281 0.00076" rpy="0 0 0"/>
        <mass value="0.07761"/>
        <inertia ixx="2e-05" ixy="0" ixz="0" iyy="4e-05" iyz="0" izz="4e-05"/>
      </inertial>
      <visual name="visual_0_RForeArm">
        <origin xyz="0 0 0" rpy="0 0 0"/>
        <geometry>
          <mesh filename="../meshes/dae/RForeArm.dae" scale="0.1 0.1 0.1"/>
        </geometry>
        <material name="RElbowRollUV"/>
      </visual>
      <collision name="collision_0_RForeArm">
        <origin xyz="0 0 0" rpy="0 0 0"/>
        <geometry>
          <box size="0.07235 0.04878 0.05006"/>
        </geometry>
      </collision>
    </link>

    <link name="RFsrFL_frame">
      <inertial>
        <origin xyz="0 0 0" rpy="0 0 0"/>
        <mass value="1e-05"/>
        <inertia ixx="2e-05" ixy="0" ixz="0" iyy="2e-05" iyz="0" izz="2e-05"/>
      </inertial>
      <collision name="collision_0_RFsrFL_frame">
        <origin xyz="0 0 0" rpy="0 0 0"/>
        <geometry>
          <box size="0.01 0.01 0.005"/>
        </geometry>
      </collision>
    </link>

    <link name="RFsrFR_frame">
      <inertial>
        <origin xyz="0 0 0" rpy="0 0 0"/>
        <mass value="1e-05"/>
        <inertia ixx="2e-05" ixy="0" ixz="0" iyy="2e-05" iyz="0" izz="2e-05"/>
      </inertial>
      <collision name="collision_0_RFsrFR_frame">
        <origin xyz="0 0 0" rpy="0 0 0"/>
        <geometry>
          <box size="0.01 0.01 0.005"/>
        </geometry>
      </collision>
    </link>

    <link name="RFsrRL_frame">
      <inertial>
        <origin xyz="0 0 0" rpy="0 0 0"/>
        <mass value="1e-05"/>
        <inertia ixx="2e-05" ixy="0" ixz="0" iyy="2e-05" iyz="0" izz="2e-05"/>
      </inertial>
      <collision name="collision_0_RFsrRL_frame">
        <origin xyz="0 0 0" rpy="0 0 0"/>
        <geometry>
          <box size="0.01 0.01 0.005"/>
        </geometry>
      </collision>
    </link>

    <link name="RFsrRR_frame">
      <inertial>
        <origin xyz="0 0 0" rpy="0 0 0"/>
        <mass value="1e-05"/>
        <inertia ixx="2e-05" ixy="0" ixz="0" iyy="2e-05" iyz="0" izz="2e-05"/>
      </inertial>
      <collision name="collision_0_RFsrRR_frame">
        <origin xyz="0 0 0" rpy="0 0 0"/>
        <geometry>
          <box size="0.01 0.01 0.005"/>
        </geometry>
      </collision>
    </link>

    <link name="RHandTouchBack_frame">
    </link>

    <link name="RHandTouchLeft_frame">
    </link>

    <link name="RHandTouchRight_frame">
    </link>

    <link name="RHip">
      <inertial>
        <origin xyz="-0.01549 -0.00029 -0.00515" rpy="0 0 0"/>
        <mass value="0.13053"/>
        <inertia ixx="2e-05" ixy="0" ixz="0" iyy="6e-05" iyz="0" izz="6e-05"/>
      </inertial>
      <visual name="visual_0_RHip">
        <origin xyz="0 0 0" rpy="0 0 0"/>
        <geometry>
          <mesh filename="../meshes/dae/RUpperThigh.dae" scale="0.1 0.1 0.1"/>
        </geometry>
        <material name="RHipRollUV"/>
      </visual>
      <collision name="collision_0_RHip">
        <origin xyz="0 0 0" rpy="0 0 0"/>
        <geometry>
          <box size="0.06259 0.03403 0.05367"/>
        </geometry>
      </collision>
    </link>

    <link name="RInfraRed_frame">
    </link>

    <link name="RPelvis">
      <inertial>
        <origin xyz="-0.00781 0.01114 0.02661" rpy="0 0 0"/>
        <mass value="0.06981"/>
        <inertia ixx="3e-05" ixy="0" ixz="0" iyy="5e-05" iyz="0" izz="5e-05"/>
      </inertial>
      <visual name="visual_0_RPelvis">
        <origin xyz="0 0 0" rpy="0 0 0"/>
        <geometry>
          <mesh filename="../meshes/dae/RHip.dae" scale="0.1 0.1 0.1"/>
        </geometry>
        <material name="RHipYawPitchUV"/>
      </visual>
      <collision name="collision_0_RPelvis">
        <origin xyz="0 0 0" rpy="0 0 0"/>
        <geometry>
          <cylinder radius="0.0414" length="0.05907"/>
        </geometry>
      </collision>
    </link>

    <link name="RShoulder">
      <inertial>
        <origin xyz="-0.00165 0.02663 0.00014" rpy="0 0 0"/>
        <mass value="0.07504"/>
        <inertia ixx="6e-05" ixy="0" ixz="0" iyy="2e-05" iyz="0" izz="6e-05"/>
      </inertial>
      <visual name="visual_0_RShoulder">
        <origin xyz="0 0 0" rpy="0 0 0"/>
        <geometry>
          <mesh filename="../meshes/dae/RShoulderPadMobil.001.dae" scale="0.1 0.1 0.1"/>
        </geometry>
        <material name="RShoulderPitchUV"/>
      </visual>
      <collision name="collision_0_RShoulder">
        <origin xyz="0 0 0" rpy="0 0 0"/>
        <geometry>
          <cylinder radius="0.03446" length="0.0675"/>
        </geometry>
      </collision>
    </link>

    <link name="RSonar_frame">
    </link>

    <link name="RThigh">
      <inertial>
        <origin xyz="0.00138 -0.00221 -0.05373" rpy="0 0 0"/>
        <mass value="0.38968"/>
        <inertia ixx="0.00051" ixy="0" ixz="6e-05" iyy="0.00047" iyz="0" izz="0.0003"/>
      </inertial>
      <visual name="visual_0_RThigh">
        <origin xyz="0 0 0" rpy="0 0 0"/>
        <geometry>
          <mesh filename="../meshes/dae/RThigh.dae" scale="0.1 0.1 0.1"/>
        </geometry>
        <material name="RHipPitchUV"/>
      </visual>
      <collision name="collision_0_RThigh">
        <origin xyz="0 0 0" rpy="0 0 0"/>
        <geometry>
          <cylinder radius="0.0481" length="0.14906"/>
        </geometry>
      </collision>
    </link>

    <link name="RThumb1_link">
      <inertial>
        <origin xyz="0 0 0" rpy="0 0 0"/>
        <mass value="1e-05"/>
        <inertia ixx="2e-05" ixy="0" ixz="0" iyy="2e-05" iyz="0" izz="2e-05"/>
      </inertial>
      <visual name="visual_0_RThumb1_link">
        <origin xyz="0 0 0" rpy="0 0 0"/>
        <geometry>
          <mesh filename="../meshes/dae/RPhalax_7.dae" scale="0.1 0.1 0.1"/>
        </geometry>
        <material name="RThumb1UV"/>
      </visual>
      <collision name="collision_0_RThumb1_link">
        <origin xyz="0 0 0" rpy="0 0 0"/>
        <geometry>
          <cylinder radius="0.00675" length="0.02155"/>
        </geometry>
      </collision>
    </link>

    <link name="RThumb2_link">
      <inertial>
        <origin xyz="0 0 0" rpy="0 0 0"/>
        <mass value="1e-05"/>
        <inertia ixx="2e-05" ixy="0" ixz="0" iyy="2e-05" iyz="0" izz="2e-05"/>
      </inertial>
      <visual name="visual_0_RThumb2_link">
        <origin xyz="0 0 0" rpy="0 0 0"/>
        <geometry>
          <mesh filename="../meshes/dae/RPhalax_8.dae" scale="0.1 0.1 0.1"/>
        </geometry>
        <material name="RThumb2UV"/>
      </visual>
      <collision name="collision_0_RThumb2_link">
        <origin xyz="0 0 0" rpy="0 0 0"/>
        <geometry>
          <cylinder radius="0.00701" length="0.02056"/>
        </geometry>
      </collision>
    </link>

    <link name="RTibia">
      <inertial>
        <origin xyz="0.00453 -0.00225 -0.04936" rpy="0 0 0"/>
        <mass value="0.29142"/>
        <inertia ixx="0.00047" ixy="0" ixz="-4e-05" iyy="0.00041" iyz="0" izz="0.00018"/>
      </inertial>
      <visual name="visual_0_RTibia">
        <origin xyz="0 0 0" rpy="0 0 0"/>
        <geometry>
          <mesh filename="../meshes/dae/RShinebone.dae" scale="0.1 0.1 0.1"/>
        </geometry>
        <material name="uvAnkle"/>
      </visual>
      <collision name="collision_0_RTibia">
        <origin xyz="0 0 0" rpy="0 0 0"/>
        <geometry>
          <cylinder radius="0.0456" length="0.1487"/>
        </geometry>
      </collision>
    </link>

    <link name="base_link">
    </link>

    <link name="gaze">
    </link>

    <link name="l_ankle">
      <inertial>
        <origin xyz="0.02542 0.0033 -0.03239" rpy="0 0 0"/>
        <mass value="0.16184"/>
        <inertia ixx="0.0001" ixy="0" ixz="0" iyy="0.00037" iyz="0" izz="0.00042"/>
      </inertial>
      <visual name="visual_0_l_ankle">
        <origin xyz="0 0 0" rpy="0 0 0"/>
        <geometry>
          <mesh filename="../meshes/dae/LFoot.dae" scale="0.1 0.1 0.1"/>
        </geometry>
        <material name="LAnkleRollUV"/>
      </visual>
      <collision name="collision_0_l_ankle">
        <origin xyz="0 0 0" rpy="0 0 0"/>
        <geometry>
          <box size="0.16386 0.09221 0.06587"/>
        </geometry>
      </collision>
    </link>

    <link name="l_gripper">
      <inertial>
        <origin xyz="0 0 0" rpy="0 0 0"/>
        <mass value="1e-05"/>
        <inertia ixx="2e-05" ixy="0" ixz="0" iyy="2e-05" iyz="0" izz="2e-05"/>
      </inertial>
    </link>

    <link name="l_sole">
    </link>

    <link name="l_wrist">
      <inertial>
        <origin xyz="0.03434 -0.00088 0.00308" rpy="0 0 0"/>
        <mass value="0.18533"/>
        <inertia ixx="7e-05" ixy="0" ixz="0" iyy="0.00014" iyz="0" izz="0.00013"/>
      </inertial>
      <visual name="visual_0_l_wrist">
        <origin xyz="0 0 0" rpy="0 0 0"/>
        <geometry>
          <mesh filename="../meshes/dae/RHand.dae" scale="0.1 0.1 0.1"/>
        </geometry>
        <material name="RWristYawUV"/>
      </visual>
      <collision name="collision_0_l_wrist">
        <origin xyz="0 0 0" rpy="0 0 0"/>
        <geometry>
          <box size="0.08481 0.06829 0.063"/>
        </geometry>
      </collision>
    </link>

    <link name="r_ankle">
      <inertial>
        <origin xyz="0.02542 -0.0033 -0.03239" rpy="0 0 0"/>
        <mass value="0.16184"/>
        <inertia ixx="0.0001" ixy="0" ixz="0" iyy="0.00037" iyz="0" izz="0.00042"/>
      </inertial>
      <visual name="visual_0_r_ankle">
        <origin xyz="0 0 0" rpy="0 0 0"/>
        <geometry>
          <mesh filename="../meshes/dae/RFoot.dae" scale="0.1 0.1 0.1"/>
        </geometry>
        <material name="RAnkleRollUV"/>
      </visual>
      <collision name="collision_0_r_ankle">
        <origin xyz="0 0 0" rpy="0 0 0"/>
        <geometry>
          <box size="0.16405 0.09226 0.06588"/>
        </geometry>
      </collision>
    </link>

    <link name="r_gripper">
      <inertial>
        <origin xyz="0 0 0" rpy="0 0 0"/>
        <mass value="1e-05"/>
        <inertia ixx="2e-05" ixy="0" ixz="0" iyy="2e-05" iyz="0" izz="2e-05"/>
      </inertial>
    </link>

    <link name="r_sole">
    </link>

    <link name="r_wrist">
      <inertial>
        <origin xyz="0.03434 0.00088 0.00308" rpy="0 0 0"/>
        <mass value="0.18533"/>
        <inertia ixx="7e-05" ixy="0" ixz="0" iyy="0.00014" iyz="0" izz="0.00013"/>
      </inertial>
      <visual name="visual_0_r_wrist">
        <origin xyz="0 0 0" rpy="0 0 0"/>
        <geometry>
          <mesh filename="../meshes/dae/RHand.001.dae" scale="0.1 0.1 0.1"/>
        </geometry>
        <material name="RWristYawUV.001"/>
      </visual>
      <collision name="collision_0_r_wrist">
        <origin xyz="0 0 0" rpy="0 0 0"/>
        <geometry>
          <box size="0.08469 0.068 0.06321"/>
        </geometry>
      </collision>
    </link>

    <link name="torso">
      <inertial>
        <origin xyz="-0.00413 0 0.04342" rpy="0 0 0"/>
        <mass value="1.04956"/>
        <inertia ixx="0.00308" ixy="0" ixz="-3e-05" iyy="0.00288" iyz="-3e-05" izz="0.00159"/>
      </inertial>
      <visual name="visual_0_torso">
        <origin xyz="0 0 0" rpy="0 0 0"/>
        <geometry>
          <mesh filename="../meshes/dae/Chest.dae" scale="0.1 0.1 0.1"/>
        </geometry>
        <material name="TorsoUV"/>
      </visual>
      <collision name="collision_0_torso">
        <origin xyz="0 0 0" rpy="0 0 0"/>
        <geometry>
          <box size="0.11168 0.174 0.23094"/>
        </geometry>
      </collision>
    </link>

    <joint name="Accelerometer_sensor_fixedjoint" type="fixed">
      <origin xyz="-0.008 0.00606 0.027" rpy="0 0 0"/>
      <parent link="torso"/>
      <child link="ImuTorsoAccelerometer_frame"/>
    </joint>

    <joint name="CameraBottom_optical_frame_fixedjoint" type="fixed">
      <origin xyz="0 0 0" rpy="-1.5708 0 -1.5708"/>
      <parent link="CameraBottom_frame"/>
      <child link="CameraBottom_optical_frame"/>
    </joint>

    <joint name="CameraBottom_sensor_fixedjoint" type="fixed">
      <origin xyz="0.05071 0 0.01774" rpy="0 0.6929 0"/>
      <parent link="Head"/>
      <child link="CameraBottom_frame"/>
    </joint>

    <joint name="CameraTop_optical_frame_fixedjoint" type="fixed">
      <origin xyz="0 0 0" rpy="-1.5708 0 -1.5708"/>
      <parent link="CameraTop_frame"/>
      <child link="CameraTop_optical_frame"/>
    </joint>

    <joint name="CameraTop_sensor_fixedjoint" type="fixed">
      <origin xyz="0.05871 0 0.06364" rpy="0 0.02094 0"/>
      <parent link="Head"/>
      <child link="CameraTop_frame"/>
    </joint>

    <joint name="ChestBoard/Button_sensor_fixedjoint" type="fixed">
      <origin xyz="0.04987 0.00159 0.05516" rpy="0 0 0"/>
      <parent link="torso"/>
      <child link="ChestButton_frame"/>
    </joint>

    <joint name="Gyrometer_sensor_fixedjoint" type="fixed">
      <origin xyz="-0.008 0.006 0.029" rpy="0 0 0"/>
      <parent link="torso"/>
      <child link="ImuTorsoGyrometer_frame"/>
    </joint>

    <joint name="Head/Touch/Front_sensor_fixedjoint" type="fixed">
      <origin xyz="0.0312 0 0.1014" rpy="0 -1.1861 0"/>
      <parent link="Head"/>
      <child link="HeadTouchFront_frame"/>
    </joint>

    <joint name="Head/Touch/Middle_sensor_fixedjoint" type="fixed">
      <origin xyz="0.001 0 0.1099" rpy="0 -1.5708 0"/>
      <parent link="Head"/>
      <child link="HeadTouchMiddle_frame"/>
    </joint>

    <joint name="Head/Touch/Rear_sensor_fixedjoint" type="fixed">
      <origin xyz="-0.0257 0 0.1045" rpy="0 -1.8084 0"/>
      <parent link="Head"/>
      <child link="HeadTouchRear_frame"/>
    </joint>

    <joint name="HeadPitch" type="revolute">
      <origin xyz="0 0 0" rpy="0 0 0"/>
      <parent link="Neck"/>
      <child link="Head"/>
      <axis xyz="0 1.0 0"/>
      <limit lower="-0.67195" upper="0.51487" effort="1.532" velocity="7.19407"/>
    </joint>

    <joint name="HeadYaw" type="revolute">
      <origin xyz="0 0 0.1265" rpy="0 0 0"/>
      <parent link="torso"/>
      <child link="Neck"/>
      <axis xyz="0 0 1.0"/>
      <limit lower="-2.08567" upper="2.08567" effort="1.547" velocity="8.26797"/>
    </joint>

    <joint name="InfraredL_sensor_fixedjoint" type="fixed">
      <origin xyz="0.0441 0.0257 0.0466" rpy="0 0 0"/>
      <parent link="Head"/>
      <child link="LInfraRed_frame"/>
    </joint>

    <joint name="InfraredR_sensor_fixedjoint" type="fixed">
      <origin xyz="0.0441 -0.0257 0.0466" rpy="0 0 0"/>
      <parent link="Head"/>
      <child link="RInfraRed_frame"/>
    </joint>

    <joint name="LAnklePitch" type="revolute">
      <origin xyz="0 0 -0.1029" rpy="0 0 0"/>
      <parent link="LTibia"/>
      <child link="LAnklePitch"/>
      <axis xyz="0 1.0 0"/>
      <limit lower="-1.18944" upper="0.92258" effort="3.023" velocity="6.40239"/>
    </joint>

    <joint name="LAnkleRoll" type="revolute">
      <origin xyz="0 0 0" rpy="0 0 0"/>
      <parent link="LAnklePitch"/>
      <child link="l_ankle"/>
      <axis xyz="1.0 0 0"/>
      <limit lower="-0.39776" upper="0.76899" effort="3.348" velocity="4.16174"/>
    </joint>

    <joint name="LElbowRoll" type="revolute">
      <origin xyz="0 0 0" rpy="0 0 0"/>
      <parent link="LElbow"/>
      <child link="LForeArm"/>
      <axis xyz="0 0 1.0"/>
      <limit lower="-1.54462" upper="-0.03491" effort="1.532" velocity="7.19407"/>
    </joint>

    <joint name="LElbowYaw" type="revolute">
      <origin xyz="0.105 0.015 0" rpy="0 0 0"/>
      <parent link="LBicep"/>
      <child link="LElbow"/>
      <axis xyz="1.0 0 0"/>
      <limit lower="-2.08567" upper="2.08567" effort="1.547" velocity="8.26797"/>
    </joint>

    <joint name="LFinger11" type="continuous">
      <origin xyz="0.06907 0.01157 -0.00304" rpy="1.8862 0.97666 0.26407"/>
      <parent link="l_wrist"/>
      <child link="LFinger11_link"/>
      <axis xyz="0 0 1.0"/>
    </joint>

    <joint name="LFinger12" type="continuous">
      <origin xyz="0.01436 0 0" rpy="0 0 -0.9999"/>
      <parent link="LFinger11_link"/>
      <child link="LFinger12_link"/>
      <axis xyz="0 0 1.0"/>
    </joint>

    <joint name="LFinger13" type="continuous">
      <origin xyz="0.01436 0 0" rpy="0 0 -0.9999"/>
      <parent link="LFinger12_link"/>
      <child link="LFinger13_link"/>
      <axis xyz="0 0 1.0"/>
    </joint>

    <joint name="LFinger21" type="continuous">
      <origin xyz="0.06907 -0.01157 -0.00304" rpy="1.25539 0.97666 -0.26407"/>
      <parent link="l_wrist"/>
      <child link="LFinger21_link"/>
      <axis xyz="0 0 1.0"/>
    </joint>

    <joint name="LFinger22" type="continuous">
      <origin xyz="0.01436 0 0" rpy="0 0 -0.9999"/>
      <parent link="LFinger21_link"/>
      <child link="LFinger22_link"/>
      <axis xyz="0 0 1.0"/>
    </joint>

    <joint name="LFinger23" type="continuous">
      <origin xyz="0.01436 0 0" rpy="0 0 -0.9999"/>
      <parent link="LFinger22_link"/>
      <child link="LFinger23_link"/>
      <axis xyz="0 0 1.0"/>
    </joint>

    <joint name="LFoot/Bumper/Left_sensor_fixedjoint" type="fixed">
      <origin xyz="0.0876 0.019 -0.0353" rpy="0 0 0"/>
      <parent link="l_ankle"/>
      <child link="LFootBumperLeft_frame"/>
    </joint>

    <joint name="LFoot/Bumper/Right_sensor_fixedjoint" type="fixed">
      <origin xyz="0.0876 -0.014 -0.0353" rpy="0 0 0"/>
      <parent link="l_ankle"/>
      <child link="LFootBumperRight_frame"/>
    </joint>

    <joint name="LFoot/FSR/FrontLeft_sensor_fixedjoint" type="fixed">
      <origin xyz="0.07025 0.0299 -0.04511" rpy="0 0 0"/>
      <parent link="l_ankle"/>
      <child link="LFsrFL_frame"/>
    </joint>

    <joint name="LFoot/FSR/FrontRight_sensor_fixedjoint" type="fixed">
      <origin xyz="0.07025 -0.0231 -0.04511" rpy="0 0 0"/>
      <parent link="l_ankle"/>
      <child link="LFsrFR_frame"/>
    </joint>

    <joint name="LFoot/FSR/RearLeft_sensor_fixedjoint" type="fixed">
      <origin xyz="-0.03025 0.0299 -0.04511" rpy="0 0 0"/>
      <parent link="l_ankle"/>
      <child link="LFsrRL_frame"/>
    </joint>

    <joint name="LFoot/FSR/RearRight_sensor_fixedjoint" type="fixed">
      <origin xyz="-0.02965 -0.0191 -0.04511" rpy="0 0 0"/>
      <parent link="l_ankle"/>
      <child link="LFsrRR_frame"/>
    </joint>

    <joint name="LHand" type="revolute">
      <origin xyz="0.05775 0 -0.01231" rpy="0 0 0"/>
      <parent link="l_wrist"/>
      <child link="l_gripper"/>
      <axis xyz="1.0 0 0"/>
      <limit lower="0" upper="1.0" effort="0.292" velocity="8.33"/>
    </joint>

    <joint name="LHand/Touch/Back_sensor_fixedjoint" type="fixed">
      <origin xyz="0.038 0 0.025" rpy="0 -1.57079 0"/>
      <parent link="l_wrist"/>
      <child link="LHandTouchBack_frame"/>
    </joint>

    <joint name="LHand/Touch/Left_sensor_fixedjoint" type="fixed">
      <origin xyz="0.032 0.025 0.003" rpy="0 0 1.5708"/>
      <parent link="l_wrist"/>
      <child link="LHandTouchLeft_frame"/>
    </joint>

    <joint name="LHand/Touch/Right_sensor_fixedjoint" type="fixed">
      <origin xyz="0.035 -0.025 0.0035" rpy="0 0 -1.5708"/>
      <parent link="l_wrist"/>
      <child link="LHandTouchRight_frame"/>
    </joint>

    <joint name="LHipPitch" type="revolute">
      <origin xyz="0 0 0" rpy="0 0 0"/>
      <parent link="LHip"/>
      <child link="LThigh"/>
      <axis xyz="0 1.0 0"/>
      <limit lower="-1.53589" upper="0.48398" effort="3.023" velocity="6.40239"/>
    </joint>

    <joint name="LHipRoll" type="revolute">
      <origin xyz="0 0 0" rpy="0 0 0"/>
      <parent link="LPelvis"/>
      <child link="LHip"/>
      <axis xyz="1.0 0 0"/>
      <limit lower="-0.37944" upper="0.79046" effort="3.348" velocity="4.16174"/>
    </joint>

    <joint name="LHipYawPitch" type="revolute">
      <origin xyz="0 0.05 -0.085" rpy="0 0 0"/>
      <parent link="torso"/>
      <child link="LPelvis"/>
      <axis xyz="0 0.70711 -0.70711"/>
      <limit lower="-1.14529" upper="0.74072" effort="3.348" velocity="4.16174"/>
    </joint>

    <joint name="LKneePitch" type="revolute">
      <origin xyz="0 0 -0.1" rpy="0 0 0"/>
      <parent link="LThigh"/>
      <child link="LTibia"/>
      <axis xyz="0 1.0 0"/>
      <limit lower="-0.09233" upper="2.11255" effort="3.023" velocity="6.40239"/>
    </joint>

    <joint name="LLeg_effector_fixedjoint" type="fixed">
      <origin xyz="0 0 -0.04511" rpy="0 0 0"/>
      <parent link="l_ankle"/>
      <child link="l_sole"/>
    </joint>

    <joint name="LShoulderPitch" type="revolute">
      <origin xyz="0 0.098 0.1" rpy="0 0 0"/>
      <parent link="torso"/>
      <child link="LShoulder"/>
      <axis xyz="0 1.0 0"/>
      <limit lower="-2.08567" upper="2.08567" effort="1.329" velocity="8.26797"/>
    </joint>

    <joint name="LShoulderRoll" type="revolute">
      <origin xyz="0 0 0" rpy="0 0 0"/>
      <parent link="LShoulder"/>
      <child link="LBicep"/>
      <axis xyz="0 0 1.0"/>
      <limit lower="-0.31416" upper="1.32645" effort="1.7835" velocity="7.19407"/>
    </joint>

    <joint name="LThumb1" type="continuous">
      <origin xyz="0.04895 0 -0.02638" rpy="-1.5708 0.0473 0"/>
      <parent link="l_wrist"/>
      <child link="LThumb1_link"/>
      <axis xyz="0 0 1.0"/>
    </joint>

    <joint name="LThumb2" type="continuous">
      <origin xyz="0.01436 0 0" rpy="0 0 -0.9999"/>
      <parent link="LThumb1_link"/>
      <child link="LThumb2_link"/>
      <axis xyz="0 0 1.0"/>
    </joint>

    <joint name="LWristYaw" type="revolute">
      <origin xyz="0.05595 0 0" rpy="0 0 0"/>
      <parent link="LForeArm"/>
      <child link="l_wrist"/>
      <axis xyz="1.0 0 0"/>
      <limit lower="-1.82387" upper="1.82387" effort="0.4075" velocity="24.6229"/>
    </joint>

    <joint name="MicroFront_sensor_fixedjoint" type="fixed">
      <origin xyz="0.041 0 0.091" rpy="0 0 0"/>
      <parent link="Head"/>
      <child link="MicroFrontCenter_frame"/>
    </joint>

    <joint name="MicroLeft_sensor_fixedjoint" type="fixed">
      <origin xyz="-0.0195 0.0606 0.0331" rpy="0 0 0"/>
      <parent link="Head"/>
      <child link="MicroSurroundLeft_frame"/>
    </joint>

    <joint name="MicroRear_sensor_fixedjoint" type="fixed">
      <origin xyz="-0.0577 0 0.0693" rpy="0 0 0"/>
      <parent link="Head"/>
      <child link="MicroRearCenter_frame"/>
    </joint>

    <joint name="MicroRight_sensor_fixedjoint" type="fixed">
      <origin xyz="-0.0195 -0.0606 0.0331" rpy="0 0 0"/>
      <parent link="Head"/>
      <child link="MicroSurroundRight_frame"/>
    </joint>

    <joint name="RAnklePitch" type="revolute">
      <origin xyz="0 0 -0.1029" rpy="0 0 0"/>
      <parent link="RTibia"/>
      <child link="RAnklePitch"/>
      <axis xyz="0 1.0 0"/>
      <limit lower="-1.1863" upper="0.93201" effort="3.0226" velocity="6.40239"/>
    </joint>

    <joint name="RAnkleRoll" type="revolute">
      <origin xyz="0 0 0" rpy="0 0 0"/>
      <parent link="RAnklePitch"/>
      <child link="r_ankle"/>
      <axis xyz="1.0 0 0"/>
      <limit lower="-0.76899" upper="0.39776" effort="3.348" velocity="4.16174"/>
    </joint>

    <joint name="RElbowRoll" type="revolute">
      <origin xyz="0 0 0" rpy="0 0 0"/>
      <parent link="RElbow"/>
      <child link="RForeArm"/>
      <axis xyz="0 0 1.0"/>
      <limit lower="0.03491" upper="1.54462" effort="1.532" velocity="7.19407"/>
    </joint>

    <joint name="RElbowYaw" type="revolute">
      <origin xyz="0.105 -0.015 0" rpy="0 0 0"/>
      <parent link="RBicep"/>
      <child link="RElbow"/>
      <axis xyz="1.0 0 0"/>
      <limit lower="-2.08567" upper="2.08567" effort="1.547" velocity="8.26797"/>
    </joint>

    <joint name="RFinger11" type="continuous">
      <origin xyz="0.06907 0.01157 -0.00304" rpy="1.8862 0.97666 0.26407"/>
      <parent link="r_wrist"/>
      <child link="RFinger11_link"/>
      <axis xyz="0 0 1.0"/>
    </joint>

    <joint name="RFinger12" type="continuous">
      <origin xyz="0.01436 0 0" rpy="0 0 -0.9999"/>
      <parent link="RFinger11_link"/>
      <child link="RFinger12_link"/>
      <axis xyz="0 0 1.0"/>
    </joint>

    <joint name="RFinger13" type="continuous">
      <origin xyz="0.01436 0 0" rpy="0 0 -0.9999"/>
      <parent link="RFinger12_link"/>
      <child link="RFinger13_link"/>
      <axis xyz="0 0 1.0"/>
    </joint>

    <joint name="RFinger21" type="continuous">
      <origin xyz="0.06907 -0.01157 -0.00304" rpy="1.25539 0.97666 -0.26407"/>
      <parent link="r_wrist"/>
      <child link="RFinger21_link"/>
      <axis xyz="0 0 1.0"/>
    </joint>

    <joint name="RFinger22" type="continuous">
      <origin xyz="0.01436 0 0" rpy="0 0 -0.9999"/>
      <parent link="RFinger21_link"/>
      <child link="RFinger22_link"/>
      <axis xyz="0 0 1.0"/>
    </joint>

    <joint name="RFinger23" type="continuous">
      <origin xyz="0.01436 0 0" rpy="0 0 -0.9999"/>
      <parent link="RFinger22_link"/>
      <child link="RFinger23_link"/>
      <axis xyz="0 0 1.0"/>
    </joint>

    <joint name="RFoot/Bumper/Left_sensor_fixedjoint" type="fixed">
      <origin xyz="0.0876 0.014 -0.0353" rpy="0 0 0"/>
      <parent link="r_ankle"/>
      <child link="RFootBumperLeft_frame"/>
    </joint>

    <joint name="RFoot/Bumper/Right_sensor_fixedjoint" type="fixed">
      <origin xyz="0.0876 -0.019 -0.0353" rpy="0 0 0"/>
      <parent link="r_ankle"/>
      <child link="RFootBumperRight_frame"/>
    </joint>

    <joint name="RFoot/FSR/FrontLeft_sensor_fixedjoint" type="fixed">
      <origin xyz="0.07025 0.0231 -0.04511" rpy="0 0 0"/>
      <parent link="r_ankle"/>
      <child link="RFsrFL_frame"/>
    </joint>

    <joint name="RFoot/FSR/FrontRight_sensor_fixedjoint" type="fixed">
      <origin xyz="0.07025 -0.0299 -0.04511" rpy="0 0 0"/>
      <parent link="r_ankle"/>
      <child link="RFsrFR_frame"/>
    </joint>

    <joint name="RFoot/FSR/RearLeft_sensor_fixedjoint" type="fixed">
      <origin xyz="-0.03025 0.0191 -0.04511" rpy="0 0 0"/>
      <parent link="r_ankle"/>
      <child link="RFsrRL_frame"/>
    </joint>

    <joint name="RFoot/FSR/RearRight_sensor_fixedjoint" type="fixed">
      <origin xyz="-0.02965 -0.0299 -0.04511" rpy="0 0 0"/>
      <parent link="r_ankle"/>
      <child link="RFsrRR_frame"/>
    </joint>

    <joint name="RHand" type="revolute">
      <origin xyz="0.05775 0 -0.01213" rpy="0 0 0"/>
      <parent link="r_wrist"/>
      <child link="r_gripper"/>
      <axis xyz="1.0 0 0"/>
      <limit lower="0" upper="1.0" effort="0.292" velocity="8.33"/>
    </joint>

    <joint name="RHand/Touch/Back_sensor_fixedjoint" type="fixed">
      <origin xyz="0.038 0 0.025" rpy="0 -1.57079 0"/>
      <parent link="r_wrist"/>
      <child link="RHandTouchBack_frame"/>
    </joint>

    <joint name="RHand/Touch/Left_sensor_fixedjoint" type="fixed">
      <origin xyz="0.032 0.025 0.003" rpy="0 0 1.5708"/>
      <parent link="r_wrist"/>
      <child link="RHandTouchLeft_frame"/>
    </joint>

    <joint name="RHand/Touch/Right_sensor_fixedjoint" type="fixed">
      <origin xyz="0.035 -0.025 0.0035" rpy="0 0 -1.5708"/>
      <parent link="r_wrist"/>
      <child link="RHandTouchRight_frame"/>
    </joint>

    <joint name="RHipPitch" type="revolute">
      <origin xyz="0 0 0" rpy="0 0 0"/>
      <parent link="RHip"/>
      <child link="RThigh"/>
      <axis xyz="0 1.0 0"/>
      <limit lower="-1.53589" upper="0.48398" effort="3.0226" velocity="6.40239"/>
    </joint>

    <joint name="RHipRoll" type="revolute">
      <origin xyz="0 0 0" rpy="0 0 0"/>
      <parent link="RPelvis"/>
      <child link="RHip"/>
      <axis xyz="1.0 0 0"/>
      <limit lower="-0.79046" upper="0.37944" effort="3.348" velocity="4.16174"/>
    </joint>

    <joint name="RHipYawPitch" type="revolute">
      <origin xyz="0 -0.05 -0.085" rpy="0 0 0"/>
      <parent link="torso"/>
      <child link="RPelvis"/>
      <axis xyz="0 0.70711 0.70711"/>
      <limit lower="-1.14529" upper="0.74072" effort="3.348" velocity="4.16174"/>
    </joint>

    <joint name="RKneePitch" type="revolute">
      <origin xyz="0 0 -0.1" rpy="0 0 0"/>
      <parent link="RThigh"/>
      <child link="RTibia"/>
      <axis xyz="0 1.0 0"/>
      <limit lower="-0.09233" upper="2.11255" effort="3.0226" velocity="6.40239"/>
    </joint>

    <joint name="RLeg_effector_fixedjoint" type="fixed">
      <origin xyz="0 0 -0.04511" rpy="0 0 0"/>
      <parent link="r_ankle"/>
      <child link="r_sole"/>
    </joint>

    <joint name="RShoulderPitch" type="revolute">
      <origin xyz="0 -0.098 0.1" rpy="0 0 0"/>
      <parent link="torso"/>
      <child link="RShoulder"/>
      <axis xyz="0 1.0 0"/>
      <limit lower="-2.08567" upper="2.08567" effort="1.329" velocity="8.26797"/>
    </joint>

    <joint name="RShoulderRoll" type="revolute">
      <origin xyz="0 0 0" rpy="0 0 0"/>
      <parent link="RShoulder"/>
      <child link="RBicep"/>
      <axis xyz="0 0 1.0"/>
      <limit lower="-1.32645" upper="0.31416" effort="1.783" velocity="7.19407"/>
    </joint>

    <joint name="RThumb1" type="continuous">
      <origin xyz="0.04895 0 -0.02638" rpy="-1.5708 0.0473 0"/>
      <parent link="r_wrist"/>
      <child link="RThumb1_link"/>
      <axis xyz="0 0 1.0"/>
    </joint>

    <joint name="RThumb2" type="continuous">
      <origin xyz="0.01436 0 0" rpy="0 0 -0.9999"/>
      <parent link="RThumb1_link"/>
      <child link="RThumb2_link"/>
      <axis xyz="0 0 1.0"/>
    </joint>

    <joint name="RWristYaw" type="revolute">
      <origin xyz="0.05595 0 0" rpy="0 0 0"/>
      <parent link="RForeArm"/>
      <child link="r_wrist"/>
      <axis xyz="1.0 0 0"/>
      <limit lower="-1.82387" upper="1.82387" effort="0.4075" velocity="24.6229"/>
    </joint>

    <joint name="Sonar/Left_sensor_fixedjoint" type="fixed">
      <origin xyz="0.00558 0.01921 0.06239" rpy="-0.00479 0.04365 0.39244"/>
      <parent link="torso"/>
      <child link="LSonar_frame"/>
    </joint>

    <joint name="Sonar/Right_sensor_fixedjoint" type="fixed">
      <origin xyz="0.00558 -0.01921 0.06239" rpy="0.00479 0.04365 -0.39244"/>
      <parent link="torso"/>
      <child link="RSonar_frame"/>
    </joint>

    <joint name="base_link_fixedjoint" type="fixed">
      <origin xyz="0 0 0" rpy="0 0 0"/>
      <parent link="base_link"/>
      <child link="torso"/>
    </joint>

    <joint name="gaze_joint" type="fixed">
      <origin xyz="0.05871 0 0.06364" rpy="0 0 0"/>
      <parent link="Head"/>
      <child link="gaze"/>
    </joint>

    <material name="HeadPitchUV">
      <color rgba="0.8 0.8 0.8 1.0"/>
    </material>

    <material name="HeadYawuv">
      <color rgba="0.8 0.8 0.8 1.0"/>
    </material>

    <material name="LAnkleRollUV">
      <color rgba="0.8 0.8 0.8 1.0"/>
    </material>

    <material name="LElbowRollUV">
      <color rgba="0.8 0.8 0.8 1.0"/>
    </material>

    <material name="LFinger11UV">
      <color rgba="0.8 0.8 0.8 1.0"/>
    </material>

    <material name="LFinger12UV">
      <color rgba="0.8 0.8 0.8 1.0"/>
    </material>

    <material name="LFinger21UV">
      <color rgba="0.8 0.8 0.8 1.0"/>
    </material>

    <material name="LFinger22UV">
      <color rgba="0.8 0.8 0.8 1.0"/>
    </material>

    <material name="LFinger23UV">
      <color rgba="0.8 0.8 0.8 1.0"/>
    </material>

    <material name="LHipPitchUV">
      <color rgba="0.8 0.8 0.8 1.0"/>
    </material>

    <material name="LHipRollUV">
      <color rgba="0.8 0.8 0.8 1.0"/>
    </material>

    <material name="LHipYawPitchUV">
      <color rgba="0.8 0.8 0.8 1.0"/>
    </material>

    <material name="LKneePitchUV">
      <color rgba="0.8 0.8 0.8 1.0"/>
    </material>

    <material name="LShoulderRollUV">
      <color rgba="0.8 0.8 0.8 1.0"/>
    </material>

    <material name="LThumb1UV">
      <color rgba="0.8 0.8 0.8 1.0"/>
    </material>

    <material name="LThumb2UV">
      <color rgba="0.8 0.8 0.8 1.0"/>
    </material>

    <material name="Lfindger13UV">
      <color rgba="0.8 0.8 0.8 1.0"/>
    </material>

    <material name="NaoMat_MainSkin.011">
      <color rgba="0.8 0.8 0.8 1.0"/>
    </material>

    <material name="RAnklePitchUV">
      <color rgba="0.8 0.8 0.8 1.0"/>
    </material>

    <material name="RAnkleRollUV">
      <color rgba="0.8 0.8 0.8 1.0"/>
    </material>

    <material name="RElbowRollUV">
      <color rgba="0.8 0.8 0.8 1.0"/>
    </material>

    <material name="RFinger11UV">
      <color rgba="0.8 0.8 0.8 1.0"/>
    </material>

    <material name="RFinger12UV">
      <color rgba="0.8 0.8 0.8 1.0"/>
    </material>

    <material name="RFinger13UV">
      <color rgba="0.8 0.8 0.8 1.0"/>
    </material>

    <material name="RFinger21UV">
      <color rgba="0.8 0.8 0.8 1.0"/>
    </material>

    <material name="RFinger22UV">
      <color rgba="0.8 0.8 0.8 1.0"/>
    </material>

    <material name="RFinger23UV">
      <color rgba="0.8 0.8 0.8 1.0"/>
    </material>

    <material name="RHipPitchUV">
      <color rgba="0.8 0.8 0.8 1.0"/>
    </material>

    <material name="RHipRollUV">
      <color rgba="0.8 0.8 0.8 1.0"/>
    </material>

    <material name="RHipYawPitchUV">
      <color rgba="0.8 0.8 0.8 1.0"/>
    </material>

    <material name="RShoulderPitchUV">
      <color rgba="0.8 0.8 0.8 1.0"/>
    </material>

    <material name="RThumb1UV">
      <color rgba="0.8 0.8 0.8 1.0"/>
    </material>

    <material name="RThumb2UV">
      <color rgba="0.8 0.8 0.8 1.0"/>
    </material>

    <material name="RWristYawUV">
      <color rgba="0.8 0.8 0.8 1.0"/>
    </material>

    <material name="RWristYawUV.001">
      <color rgba="0.8 0.8 0.8 1.0"/>
    </material>

    <material name="RanklePitchUV">
      <color rgba="0.8 0.8 0.8 1.0"/>
    </material>

    <material name="RshoulderRollUV">
      <color rgba="0.8 0.8 0.8 1.0"/>
    </material>

    <material name="TorsoUV">
      <color rgba="0.8 0.8 0.8 1.0"/>
    </material>

    <material name="uvAnkle">
      <color rgba="0.8 0.8 0.8 1.0"/>
    </material>

  </robot>
