<robot name="NaoH25V40" version="1.0">
  <joint name="Accelerometer_sensor_fixedjoint" type="fixed">
    <origin rpy="0.00000 0.00000 0.00000" xyz="-0.00800 0.00606 0.02700"/>
    <parent link="torso"/>
    <child link="ImuTorsoAccelerometer_frame"/>
  </joint>
  <joint name="CameraBottom_optical_frame_fixedjoint" type="fixed">
    <origin rpy="-1.57080 -0.00000 -1.57080" xyz="0.00000 0.00000 0.00000"/>
    <parent link="CameraBottom_frame"/>
    <child link="CameraBottom_optical_frame"/>
  </joint>
  <joint name="CameraBottom_sensor_fixedjoint" type="fixed">
    <origin rpy="0.00000 0.69290 0.00000" xyz="0.05071 0.00000 0.01774"/>
    <parent link="Head"/>
    <child link="CameraBottom_frame"/>
  </joint>
  <joint name="CameraTop_optical_frame_fixedjoint" type="fixed">
    <origin rpy="-1.57080 0.00000 -1.57080" xyz="-0.00000 0.00000 0.00000"/>
    <parent link="CameraTop_frame"/>
    <child link="CameraTop_optical_frame"/>
  </joint>
  <joint name="CameraTop_sensor_fixedjoint" type="fixed">
    <origin rpy="0.00000 0.02094 0.00000" xyz="0.05871 0.00000 0.06364"/>
    <parent link="Head"/>
    <child link="CameraTop_frame"/>
  </joint>
  <joint name="ChestBoard/Button_sensor_fixedjoint" type="fixed">
    <origin rpy="0.00000 0.00000 0.00000" xyz="0.04987 0.00159 0.05516"/>
    <parent link="torso"/>
    <child link="ChestButton_frame"/>
  </joint>
  <joint name="Gyrometer_sensor_fixedjoint" type="fixed">
    <origin rpy="0.00000 0.00000 0.00000" xyz="-0.00800 0.00600 0.02900"/>
    <parent link="torso"/>
    <child link="ImuTorsoGyrometer_frame"/>
  </joint>
  <joint name="Head/Touch/Front_sensor_fixedjoint" type="fixed">
    <origin rpy="0.00000 -1.18610 0.00000" xyz="0.03120 0.00000 0.10140"/>
    <parent link="Head"/>
    <child link="HeadTouchFront_frame"/>
  </joint>
  <joint name="Head/Touch/Middle_sensor_fixedjoint" type="fixed">
    <origin rpy="3.14159 -1.57079 -3.14159" xyz="0.00100 0.00000 0.10990"/>
    <parent link="Head"/>
    <child link="HeadTouchMiddle_frame"/>
  </joint>
  <joint name="Head/Touch/Rear_sensor_fixedjoint" type="fixed">
    <origin rpy="3.14159 -1.33319 -3.14159" xyz="-0.02570 0.00000 0.10450"/>
    <parent link="Head"/>
    <child link="HeadTouchRear_frame"/>
  </joint>
  <joint name="HeadPitch" type="revolute">
    <limit lower="-0.67195" upper="0.51487" effort="1.53200" velocity="7.19407"/>
    <origin rpy="0.00000 0.00000 0.00000" xyz="0.00000 0.00000 0.00000"/>
    <parent link="Neck"/>
    <child link="Head"/>
    <axis xyz="0.00000 1.00000 0.00000"/>
  </joint>
  <joint name="HeadYaw" type="revolute">
    <limit lower="-2.08567" upper="2.08567" effort="1.54700" velocity="8.26797"/>
    <origin rpy="0.00000 0.00000 0.00000" xyz="0.00000 0.00000 0.12650"/>
    <parent link="torso"/>
    <child link="Neck"/>
    <axis xyz="0.00000 0.00000 1.00000"/>
  </joint>
  <joint name="InfraredL_sensor_fixedjoint" type="fixed">
    <origin rpy="0.00000 0.00000 0.00000" xyz="0.04410 0.02570 0.04660"/>
    <parent link="Head"/>
    <child link="LInfraRed_frame"/>
  </joint>
  <joint name="InfraredR_sensor_fixedjoint" type="fixed">
    <origin rpy="0.00000 0.00000 0.00000" xyz="0.04410 -0.02570 0.04660"/>
    <parent link="Head"/>
    <child link="RInfraRed_frame"/>
  </joint>
  <joint name="LAnklePitch" type="revolute">
    <limit lower="-1.18944" upper="0.92258" effort="3.02300" velocity="6.40239"/>
    <origin rpy="0.00000 0.00000 0.00000" xyz="0.00000 0.00000 -0.10290"/>
    <parent link="LTibia"/>
    <child link="LAnklePitch"/>
    <axis xyz="0.00000 1.00000 0.00000"/>
  </joint>
  <joint name="LAnkleRoll" type="revolute">
    <limit lower="-0.39776" upper="0.76899" effort="3.34800" velocity="4.16174"/>
    <origin rpy="0.00000 0.00000 0.00000" xyz="0.00000 0.00000 0.00000"/>
    <parent link="LAnklePitch"/>
    <child link="l_ankle"/>
    <axis xyz="1.00000 0.00000 0.00000"/>
  </joint>
  <joint name="LElbowRoll" type="revolute">
    <limit lower="-1.54462" upper="-0.03491" effort="1.53200" velocity="7.19407"/>
    <origin rpy="0.00000 0.00000 0.00000" xyz="0.00000 0.00000 0.00000"/>
    <parent link="LElbow"/>
    <child link="LForeArm"/>
    <axis xyz="0.00000 0.00000 1.00000"/>
  </joint>
  <joint name="LElbowYaw" type="revolute">
    <limit lower="-2.08567" upper="2.08567" effort="1.54700" velocity="8.26797"/>
    <origin rpy="0.00000 0.00000 0.00000" xyz="0.10500 0.01500 0.00000"/>
    <parent link="LBicep"/>
    <child link="LElbow"/>
    <axis xyz="1.00000 0.00000 0.00000"/>
  </joint>
  <joint name="LFinger11" type="continuous">
    <limit lower="0.00000" upper="0.00000" effort="0.00000" velocity="0.00000"/>
    <origin rpy="1.88620 0.97666 0.26407" xyz="0.06907 0.01157 -0.00304"/>
    <parent link="l_wrist"/>
    <child link="LFinger11_link"/>
    <axis xyz="0.00000 0.00000 1.00000"/>
  </joint>
  <joint name="LFinger12" type="continuous">
    <limit lower="0.00000" upper="0.00000" effort="0.00000" velocity="0.00000"/>
    <origin rpy="0.00000 -0.00000 -0.99990" xyz="0.01436 -0.00000 0.00000"/>
    <parent link="LFinger11_link"/>
    <child link="LFinger12_link"/>
    <axis xyz="0.00000 0.00000 1.00000"/>
  </joint>
  <joint name="LFinger13" type="continuous">
    <limit lower="0.00000" upper="0.00000" effort="0.00000" velocity="0.00000"/>
    <origin rpy="-0.00000 -0.00000 -0.99990" xyz="0.01436 -0.00000 -0.00000"/>
    <parent link="LFinger12_link"/>
    <child link="LFinger13_link"/>
    <axis xyz="0.00000 0.00000 1.00000"/>
  </joint>
  <joint name="LFinger21" type="continuous">
    <limit lower="0.00000" upper="0.00000" effort="0.00000" velocity="0.00000"/>
    <origin rpy="1.25539 0.97666 -0.26407" xyz="0.06907 -0.01157 -0.00304"/>
    <parent link="l_wrist"/>
    <child link="LFinger21_link"/>
    <axis xyz="0.00000 0.00000 1.00000"/>
  </joint>
  <joint name="LFinger22" type="continuous">
    <limit lower="0.00000" upper="0.00000" effort="0.00000" velocity="0.00000"/>
    <origin rpy="-0.00000 0.00000 -0.99990" xyz="0.01436 -0.00000 -0.00000"/>
    <parent link="LFinger21_link"/>
    <child link="LFinger22_link"/>
    <axis xyz="0.00000 0.00000 1.00000"/>
  </joint>
  <joint name="LFinger23" type="continuous">
    <limit lower="0.00000" upper="0.00000" effort="0.00000" velocity="0.00000"/>
    <origin rpy="0.00000 -0.00000 -0.99990" xyz="0.01436 -0.00000 -0.00000"/>
    <parent link="LFinger22_link"/>
    <child link="LFinger23_link"/>
    <axis xyz="0.00000 0.00000 1.00000"/>
  </joint>
  <joint name="LFoot/Bumper/Left_sensor_fixedjoint" type="fixed">
    <origin rpy="0.00000 0.00000 0.00000" xyz="0.08760 0.01900 -0.03530"/>
    <parent link="l_ankle"/>
    <child link="LFootBumperLeft_frame"/>
  </joint>
  <joint name="LFoot/Bumper/Right_sensor_fixedjoint" type="fixed">
    <origin rpy="0.00000 0.00000 0.00000" xyz="0.08760 -0.01400 -0.03530"/>
    <parent link="l_ankle"/>
    <child link="LFootBumperRight_frame"/>
  </joint>
  <joint name="LFoot/FSR/FrontLeft_sensor_fixedjoint" type="fixed">
    <origin rpy="0.00000 0.00000 0.00000" xyz="0.07025 0.02990 -0.04511"/>
    <parent link="l_ankle"/>
    <child link="LFsrFL_frame"/>
  </joint>
  <joint name="LFoot/FSR/FrontRight_sensor_fixedjoint" type="fixed">
    <origin rpy="0.00000 0.00000 0.00000" xyz="0.07025 -0.02310 -0.04511"/>
    <parent link="l_ankle"/>
    <child link="LFsrFR_frame"/>
  </joint>
  <joint name="LFoot/FSR/RearLeft_sensor_fixedjoint" type="fixed">
    <origin rpy="0.00000 0.00000 0.00000" xyz="-0.03025 0.02990 -0.04511"/>
    <parent link="l_ankle"/>
    <child link="LFsrRL_frame"/>
  </joint>
  <joint name="LFoot/FSR/RearRight_sensor_fixedjoint" type="fixed">
    <origin rpy="0.00000 0.00000 0.00000" xyz="-0.02965 -0.01910 -0.04511"/>
    <parent link="l_ankle"/>
    <child link="LFsrRR_frame"/>
  </joint>
  <joint name="LHand" type="revolute">
    <limit lower="0" upper="1.00000" effort="0.29200" velocity="8.33000"/>
    <origin rpy="0.00000 0.00000 0.00000" xyz="0.05775 -0.00000 -0.01231"/>
    <parent link="l_wrist"/>
    <child link="l_gripper"/>
    <axis xyz="1.00000 0.00000 0.00000"/>
  </joint>
  <joint name="LHand/Touch/Back_sensor_fixedjoint" type="fixed">
    <origin rpy="-0.00042 -1.57079 0.00012" xyz="0.03800 0.00000 0.02500"/>
    <parent link="l_wrist"/>
    <child link="LHandTouchBack_frame"/>
  </joint>
  <joint name="LHand/Touch/Left_sensor_fixedjoint" type="fixed">
    <origin rpy="0.00000 0.00000 1.57080" xyz="0.03200 0.02500 0.00300"/>
    <parent link="l_wrist"/>
    <child link="LHandTouchLeft_frame"/>
  </joint>
  <joint name="LHand/Touch/Right_sensor_fixedjoint" type="fixed">
    <origin rpy="0.00000 0.00000 -1.57080" xyz="0.03500 -0.02500 0.00350"/>
    <parent link="l_wrist"/>
    <child link="LHandTouchRight_frame"/>
  </joint>
  <joint name="LHipPitch" type="revolute">
    <limit lower="-1.53589" upper="0.48398" effort="3.02300" velocity="6.40239"/>
    <origin rpy="0.00000 0.00000 0.00000" xyz="0.00000 0.00000 0.00000"/>
    <parent link="LHip"/>
    <child link="LThigh"/>
    <axis xyz="0.00000 1.00000 0.00000"/>
  </joint>
  <joint name="LHipRoll" type="revolute">
    <limit lower="-0.37944" upper="0.79046" effort="3.34800" velocity="4.16174"/>
    <origin rpy="0.00000 0.00000 0.00000" xyz="0.00000 0.00000 0.00000"/>
    <parent link="LPelvis"/>
    <child link="LHip"/>
    <axis xyz="1.00000 0.00000 0.00000"/>
  </joint>
  <joint name="LHipYawPitch" type="revolute">
    <limit lower="-1.14529" upper="0.74072" effort="3.34800" velocity="4.16174"/>
    <origin rpy="0.00000 0.00000 0.00000" xyz="0.00000 0.05000 -0.08500"/>
    <parent link="torso"/>
    <child link="LPelvis"/>
    <axis xyz="0.00000 0.70711 -0.70711"/>
  </joint>
  <joint name="LKneePitch" type="revolute">
    <limit lower="-0.09233" upper="2.11255" effort="3.02300" velocity="6.40239"/>
    <origin rpy="0.00000 0.00000 0.00000" xyz="0.00000 0.00000 -0.10000"/>
    <parent link="LThigh"/>
    <child link="LTibia"/>
    <axis xyz="0.00000 1.00000 0.00000"/>
  </joint>
  <joint name="LLeg_effector_fixedjoint" type="fixed">
    <origin rpy="0.00000 0.00000 0.00000" xyz="0.00000 0.00000 -0.04511"/>
    <parent link="l_ankle"/>
    <child link="l_sole"/>
  </joint>
  <joint name="LShoulderPitch" type="revolute">
    <limit lower="-2.08567" upper="2.08567" effort="1.32900" velocity="8.26797"/>
    <origin rpy="0.00000 0.00000 0.00000" xyz="0.00000 0.09800 0.10000"/>
    <parent link="torso"/>
    <child link="LShoulder"/>
    <axis xyz="0.00000 1.00000 0.00000"/>
  </joint>
  <joint name="LShoulderRoll" type="revolute">
    <limit lower="-0.31416" upper="1.32645" effort="1.78350" velocity="7.19407"/>
    <origin rpy="0.00000 0.00000 0.00000" xyz="0.00000 0.00000 0.00000"/>
    <parent link="LShoulder"/>
    <child link="LBicep"/>
    <axis xyz="0.00000 0.00000 1.00000"/>
  </joint>
  <joint name="LThumb1" type="continuous">
    <limit lower="0.00000" upper="0.00000" effort="0.00000" velocity="0.00000"/>
    <origin rpy="-1.57080 0.04730 -0.00000" xyz="0.04895 0.00000 -0.02638"/>
    <parent link="l_wrist"/>
    <child link="LThumb1_link"/>
    <axis xyz="0.00000 0.00000 1.00000"/>
  </joint>
  <joint name="LThumb2" type="continuous">
    <limit lower="0.00000" upper="0.00000" effort="0.00000" velocity="0.00000"/>
    <origin rpy="0.00000 -0.00000 -0.99990" xyz="0.01436 -0.00000 -0.00000"/>
    <parent link="LThumb1_link"/>
    <child link="LThumb2_link"/>
    <axis xyz="0.00000 0.00000 1.00000"/>
  </joint>
  <joint name="LWristYaw" type="revolute">
    <limit lower="-1.82387" upper="1.82387" effort="0.40750" velocity="24.62290"/>
    <origin rpy="0.00000 0.00000 -0.03491" xyz="0.05592 -0.00195 0.00000"/>
    <parent link="LForeArm"/>
    <child link="l_wrist"/>
    <axis xyz="1.00000 0.00000 0.00000"/>
  </joint>
  <joint name="MicroFront_sensor_fixedjoint" type="fixed">
    <origin rpy="0.00000 0.00000 0.00000" xyz="0.04100 0.00000 0.09100"/>
    <parent link="Head"/>
    <child link="MicroFrontCenter_frame"/>
  </joint>
  <joint name="MicroLeft_sensor_fixedjoint" type="fixed">
    <origin rpy="0.00000 0.00000 0.00000" xyz="-0.01950 0.06060 0.03310"/>
    <parent link="Head"/>
    <child link="MicroSurroundLeft_frame"/>
  </joint>
  <joint name="MicroRear_sensor_fixedjoint" type="fixed">
    <origin rpy="0.00000 0.00000 0.00000" xyz="-0.05770 0.00000 0.06930"/>
    <parent link="Head"/>
    <child link="MicroRearCenter_frame"/>
  </joint>
  <joint name="MicroRight_sensor_fixedjoint" type="fixed">
    <origin rpy="0.00000 0.00000 0.00000" xyz="-0.01950 -0.06060 0.03310"/>
    <parent link="Head"/>
    <child link="MicroSurroundRight_frame"/>
  </joint>
  <joint name="RAnklePitch" type="revolute">
    <limit lower="-1.18630" upper="0.93201" effort="3.02260" velocity="6.40239"/>
    <origin rpy="0.00000 0.00000 0.00000" xyz="0.00000 0.00000 -0.10290"/>
    <parent link="RTibia"/>
    <child link="RAnklePitch"/>
    <axis xyz="0.00000 1.00000 0.00000"/>
  </joint>
  <joint name="RAnkleRoll" type="revolute">
    <limit lower="-0.76899" upper="0.39776" effort="3.34800" velocity="4.16174"/>
    <origin rpy="0.00000 0.00000 0.00000" xyz="0.00000 0.00000 0.00000"/>
    <parent link="RAnklePitch"/>
    <child link="r_ankle"/>
    <axis xyz="1.00000 0.00000 0.00000"/>
  </joint>
  <joint name="RElbowRoll" type="revolute">
    <limit lower="0.03491" upper="1.54462" effort="1.53200" velocity="7.19407"/>
    <origin rpy="0.00000 0.00000 0.00000" xyz="0.00000 0.00000 0.00000"/>
    <parent link="RElbow"/>
    <child link="RForeArm"/>
    <axis xyz="0.00000 0.00000 1.00000"/>
  </joint>
  <joint name="RElbowYaw" type="revolute">
    <limit lower="-2.08567" upper="2.08567" effort="1.54700" velocity="8.26797"/>
    <origin rpy="0.00000 0.00000 0.00000" xyz="0.10500 -0.01500 0.00000"/>
    <parent link="RBicep"/>
    <child link="RElbow"/>
    <axis xyz="1.00000 0.00000 0.00000"/>
  </joint>
  <joint name="RFinger11" type="continuous">
    <limit lower="0.00000" upper="0.00000" effort="0.00000" velocity="0.00000"/>
    <origin rpy="1.88620 0.97666 0.26407" xyz="0.06907 0.01157 -0.00304"/>
    <parent link="r_wrist"/>
    <child link="RFinger11_link"/>
    <axis xyz="0.00000 0.00000 1.00000"/>
  </joint>
  <joint name="RFinger12" type="continuous">
    <limit lower="0.00000" upper="0.00000" effort="0.00000" velocity="0.00000"/>
    <origin rpy="-0.00000 0.00000 -0.99990" xyz="0.01436 0.00000 0.00000"/>
    <parent link="RFinger11_link"/>
    <child link="RFinger12_link"/>
    <axis xyz="0.00000 0.00000 1.00000"/>
  </joint>
  <joint name="RFinger13" type="continuous">
    <limit lower="0.00000" upper="0.00000" effort="0.00000" velocity="0.00000"/>
    <origin rpy="0.00000 -0.00000 -0.99990" xyz="0.01436 -0.00000 -0.00000"/>
    <parent link="RFinger12_link"/>
    <child link="RFinger13_link"/>
    <axis xyz="0.00000 0.00000 1.00000"/>
  </joint>
  <joint name="RFinger21" type="continuous">
    <limit lower="0.00000" upper="0.00000" effort="0.00000" velocity="0.00000"/>
    <origin rpy="1.25539 0.97666 -0.26407" xyz="0.06907 -0.01157 -0.00304"/>
    <parent link="r_wrist"/>
    <child link="RFinger21_link"/>
    <axis xyz="0.00000 0.00000 1.00000"/>
  </joint>
  <joint name="RFinger22" type="continuous">
    <limit lower="0.00000" upper="0.00000" effort="0.00000" velocity="0.00000"/>
    <origin rpy="0.00000 -0.00000 -0.99990" xyz="0.01436 -0.00000 0.00000"/>
    <parent link="RFinger21_link"/>
    <child link="RFinger22_link"/>
    <axis xyz="0.00000 0.00000 1.00000"/>
  </joint>
  <joint name="RFinger23" type="continuous">
    <limit lower="0.00000" upper="0.00000" effort="0.00000" velocity="0.00000"/>
    <origin rpy="0.00000 0.00000 -0.99990" xyz="0.01436 0.00000 0.00000"/>
    <parent link="RFinger22_link"/>
    <child link="RFinger23_link"/>
    <axis xyz="0.00000 0.00000 1.00000"/>
  </joint>
  <joint name="RFoot/Bumper/Left_sensor_fixedjoint" type="fixed">
    <origin rpy="0.00000 0.00000 0.00000" xyz="0.08760 0.01400 -0.03530"/>
    <parent link="r_ankle"/>
    <child link="RFootBumperLeft_frame"/>
  </joint>
  <joint name="RFoot/Bumper/Right_sensor_fixedjoint" type="fixed">
    <origin rpy="0.00000 0.00000 0.00000" xyz="0.08760 -0.01900 -0.03530"/>
    <parent link="r_ankle"/>
    <child link="RFootBumperRight_frame"/>
  </joint>
  <joint name="RFoot/FSR/FrontLeft_sensor_fixedjoint" type="fixed">
    <origin rpy="0.00000 0.00000 0.00000" xyz="0.07025 0.02310 -0.04511"/>
    <parent link="r_ankle"/>
    <child link="RFsrFL_frame"/>
  </joint>
  <joint name="RFoot/FSR/FrontRight_sensor_fixedjoint" type="fixed">
    <origin rpy="0.00000 0.00000 0.00000" xyz="0.07025 -0.02990 -0.04511"/>
    <parent link="r_ankle"/>
    <child link="RFsrFR_frame"/>
  </joint>
  <joint name="RFoot/FSR/RearLeft_sensor_fixedjoint" type="fixed">
    <origin rpy="0.00000 0.00000 0.00000" xyz="-0.03025 0.01910 -0.04511"/>
    <parent link="r_ankle"/>
    <child link="RFsrRL_frame"/>
  </joint>
  <joint name="RFoot/FSR/RearRight_sensor_fixedjoint" type="fixed">
    <origin rpy="0.00000 0.00000 0.00000" xyz="-0.02965 -0.02990 -0.04511"/>
    <parent link="r_ankle"/>
    <child link="RFsrRR_frame"/>
  </joint>
  <joint name="RHand" type="revolute">
    <limit lower="0" upper="1.00000" effort="0.29200" velocity="8.33000"/>
    <origin rpy="0.00000 0.00000 -0.00000" xyz="0.05775 0.00000 -0.01213"/>
    <parent link="r_wrist"/>
    <child link="r_gripper"/>
    <axis xyz="1.00000 0.00000 0.00000"/>
  </joint>
  <joint name="RHand/Touch/Back_sensor_fixedjoint" type="fixed">
    <origin rpy="0.00001 -1.57079 0.00096" xyz="0.03800 -0.00000 0.02500"/>
    <parent link="r_wrist"/>
    <child link="RHandTouchBack_frame"/>
  </joint>
  <joint name="RHand/Touch/Left_sensor_fixedjoint" type="fixed">
    <origin rpy="0.00000 0.00000 1.57080" xyz="0.03200 0.02500 0.00300"/>
    <parent link="r_wrist"/>
    <child link="RHandTouchLeft_frame"/>
  </joint>
  <joint name="RHand/Touch/Right_sensor_fixedjoint" type="fixed">
    <origin rpy="0.00000 0.00000 -1.57080" xyz="0.03500 -0.02500 0.00350"/>
    <parent link="r_wrist"/>
    <child link="RHandTouchRight_frame"/>
  </joint>
  <joint name="RHipPitch" type="revolute">
    <limit lower="-1.53589" upper="0.48398" effort="3.02260" velocity="6.40239"/>
    <origin rpy="0.00000 0.00000 0.00000" xyz="0.00000 0.00000 0.00000"/>
    <parent link="RHip"/>
    <child link="RThigh"/>
    <axis xyz="0.00000 1.00000 0.00000"/>
  </joint>
  <joint name="RHipRoll" type="revolute">
    <limit lower="-0.79046" upper="0.37944" effort="3.34800" velocity="4.16174"/>
    <origin rpy="0.00000 0.00000 0.00000" xyz="0.00000 0.00000 0.00000"/>
    <parent link="RPelvis"/>
    <child link="RHip"/>
    <axis xyz="1.00000 0.00000 0.00000"/>
  </joint>
  <joint name="RHipYawPitch" type="revolute">
    <limit lower="-1.14529" upper="0.74072" effort="3.34800" velocity="4.16174"/>
    <origin rpy="0.00000 0.00000 0.00000" xyz="0.00000 -0.05000 -0.08500"/>
    <parent link="torso"/>
    <child link="RPelvis"/>
    <axis xyz="0.00000 0.70711 0.70711"/>
  </joint>
  <joint name="RKneePitch" type="revolute">
    <limit lower="-0.09233" upper="2.11255" effort="3.02260" velocity="6.40239"/>
    <origin rpy="0.00000 0.00000 0.00000" xyz="0.00000 0.00000 -0.10000"/>
    <parent link="RThigh"/>
    <child link="RTibia"/>
    <axis xyz="0.00000 1.00000 0.00000"/>
  </joint>
  <joint name="RLeg_effector_fixedjoint" type="fixed">
    <origin rpy="0.00000 0.00000 0.00000" xyz="0.00000 0.00000 -0.04511"/>
    <parent link="r_ankle"/>
    <child link="r_sole"/>
  </joint>
  <joint name="RShoulderPitch" type="revolute">
    <limit lower="-2.08567" upper="2.08567" effort="1.32900" velocity="8.26797"/>
    <origin rpy="0.00000 0.00000 0.00000" xyz="0.00000 -0.09800 0.10000"/>
    <parent link="torso"/>
    <child link="RShoulder"/>
    <axis xyz="0.00000 1.00000 0.00000"/>
  </joint>
  <joint name="RShoulderRoll" type="revolute">
    <limit lower="-1.32645" upper="0.31416" effort="1.78300" velocity="7.19407"/>
    <origin rpy="0.00000 0.00000 0.00000" xyz="0.00000 0.00000 0.00000"/>
    <parent link="RShoulder"/>
    <child link="RBicep"/>
    <axis xyz="0.00000 0.00000 1.00000"/>
  </joint>
  <joint name="RThumb1" type="continuous">
    <limit lower="0.00000" upper="0.00000" effort="0.00000" velocity="0.00000"/>
    <origin rpy="-1.57080 0.04730 -0.00000" xyz="0.04895 -0.00000 -0.02638"/>
    <parent link="r_wrist"/>
    <child link="RThumb1_link"/>
    <axis xyz="0.00000 0.00000 1.00000"/>
  </joint>
  <joint name="RThumb2" type="continuous">
    <limit lower="0.00000" upper="0.00000" effort="0.00000" velocity="0.00000"/>
    <origin rpy="0.00000 -0.00000 -0.99990" xyz="0.01436 -0.00000 0.00000"/>
    <parent link="RThumb1_link"/>
    <child link="RThumb2_link"/>
    <axis xyz="0.00000 0.00000 1.00000"/>
  </joint>
  <joint name="RWristYaw" type="revolute">
    <limit lower="-1.82387" upper="1.82387" effort="0.40750" velocity="24.62290"/>
    <origin rpy="0.00000 0.00000 0.03491" xyz="0.05592 0.00195 0.00000"/>
    <parent link="RForeArm"/>
    <child link="r_wrist"/>
    <axis xyz="1.00000 0.00000 0.00000"/>
  </joint>
  <joint name="Sonar/Left_sensor_fixedjoint" type="fixed">
    <origin rpy="-0.00479 0.04365 0.39244" xyz="0.00558 0.01921 0.06239"/>
    <parent link="torso"/>
    <child link="LSonar_frame"/>
  </joint>
  <joint name="Sonar/Right_sensor_fixedjoint" type="fixed">
    <origin rpy="0.00479 0.04365 -0.39244" xyz="0.00558 -0.01921 0.06239"/>
    <parent link="torso"/>
    <child link="RSonar_frame"/>
  </joint>
  <joint name="base_link_fixedjoint" type="fixed">
    <origin rpy="0.00000 0.00000 0.00000" xyz="0.00000 0.00000 0.00000"/>
    <parent link="base_link"/>
    <child link="torso"/>
  </joint>
  <joint name="gaze_joint" type="fixed">
    <origin rpy="0.00000 0.00000 0.00000" xyz="0.05871 0.00000 0.06364"/>
    <parent link="Head"/>
    <child link="gaze"/>
  </joint>
  <link name="CameraBottom_frame"/>
  <link name="CameraBottom_optical_frame"/>
  <link name="CameraTop_frame"/>
  <link name="CameraTop_optical_frame"/>
  <link name="ChestButton_frame"/>
  <link name="Head">
    <collision name="Head_collision_collision">
      <origin rpy="0.00000 0.00000 0.00000" xyz="-0.00093 -0.00005 0.05727"/>
      <geometry>
        <box size="0.11936 0.13267 0.11439"/>
      </geometry>
    </collision>
    <inertial>
      <inertia ixx="0.00096" ixy="0.00001" ixz="0.00001" iyy="0.00082" iyz="-0.00003" izz="0.00098"/>
      <origin rpy="0.00000 0.00000 0.00000" xyz="-0.00112 0.00000 0.05258"/>
      <mass value="0.60533"/>
    </inertial>
    <visual name="Head_collision">
      <origin rpy="0.00000 0.00000 0.00000" xyz="0.00000 0.00000 0.00000"/>
      <material name="phobos_collision"/>
      <geometry>
        <mesh filename="../meshes/stl/HeadPitch_0.10.stl" scale="0.10000 0.10000 0.10000"/>
      </geometry>
    </visual>
  </link>
  <link name="HeadTouchFront_frame"/>
  <link name="HeadTouchMiddle_frame"/>
  <link name="HeadTouchRear_frame"/>
  <link name="ImuTorsoAccelerometer_frame"/>
  <link name="ImuTorsoGyrometer_frame"/>
  <link name="LAnklePitch">
    <collision name="LAnklePitch_collision_collision">
      <origin rpy="0.00000 0.00000 0.00000" xyz="-0.00169 0.00157 0.01187"/>
      <geometry>
        <box size="0.07146 0.03136 0.06369"/>
      </geometry>
    </collision>
    <inertial>
      <inertia ixx="0.00003" ixy="-0.00000" ixz="0.00000" iyy="0.00007" iyz="0.00000" izz="0.00005"/>
      <origin rpy="0.00000 0.00000 0.00000" xyz="0.00045 0.00029 0.00685"/>
      <mass value="0.13416"/>
    </inertial>
    <visual name="LAnklePitch_collision">
      <origin rpy="0.00000 0.00000 0.00000" xyz="0.00000 0.00000 0.00000"/>
      <material name="phobos_collision"/>
      <geometry>
        <mesh filename="../meshes/stl/LAnklePitch_0.10.stl" scale="0.10000 0.10000 0.10000"/>
      </geometry>
    </visual>
  </link>
  <link name="LBicep">
    <collision name="LBicep_collision_collision">
      <origin rpy="0.00000 0.00000 0.00000" xyz="0.03732 0.00600 -0.00012"/>
      <geometry>
        <box size="0.16906 0.06238 0.08158"/>
      </geometry>
    </collision>
    <inertial>
      <inertia ixx="0.00009" ixy="-0.00003" ixz="-0.00001" iyy="0.00027" iyz="0.00000" izz="0.00024"/>
      <origin rpy="0.00000 0.00000 0.00000" xyz="0.02455 0.00563 0.00330"/>
      <mass value="0.15777"/>
    </inertial>
    <visual name="LBicep_collision">
      <origin rpy="0.00000 0.00000 0.00000" xyz="0.00000 0.00000 0.00000"/>
      <material name="phobos_collision"/>
      <geometry>
        <mesh filename="../meshes/stl/LShoulderRoll_0.10.stl" scale="0.10000 0.10000 0.10000"/>
      </geometry>
    </visual>
  </link>
  <link name="LElbow">
    <inertial>
      <inertia ixx="0.00001" ixy="0.00000" ixz="0.00000" iyy="0.00003" iyz="-0.00000" izz="0.00003"/>
      <origin rpy="0.00000 0.00000 0.00000" xyz="-0.02744 0.00000 -0.00014"/>
      <mass value="0.06483"/>
    </inertial>
  </link>
  <link name="LFinger11_link">
    <collision name="LFinger11_link_collision_collision">
      <origin rpy="-0.00000 0.00000 -0.00000" xyz="0.00771 -0.00039 -0.00050"/>
      <geometry>
        <box size="0.01954 0.01519 0.01232"/>
      </geometry>
    </collision>
    <inertial>
      <inertia ixx="0.00000" ixy="0.00000" ixz="0.00000" iyy="0.00000" iyz="0.00000" izz="0.00000"/>
      <origin rpy="0.00000 0.00000 0.00000" xyz="0.00000 0.00000 0.00000"/>
      <mass value="0.00000"/>
    </inertial>
    <visual name="LFinger11_link_collision">
      <origin rpy="0.00000 0.00000 0.00000" xyz="-0.00000 0.00000 -0.00000"/>
      <material name="phobos_collision"/>
      <geometry>
        <mesh filename="../meshes/stl/LFinger11_0.10.stl" scale="0.10000 0.10000 0.10000"/>
      </geometry>
    </visual>
  </link>
  <link name="LFinger12_link">
    <collision name="LFinger12_link_collision_collision">
      <origin rpy="-0.00000 -0.00000 -0.00000" xyz="0.00771 -0.00060 -0.00034"/>
      <geometry>
        <box size="0.01954 0.01519 0.01232"/>
      </geometry>
    </collision>
    <inertial>
      <inertia ixx="0.00000" ixy="0.00000" ixz="-0.00000" iyy="0.00000" iyz="-0.00000" izz="0.00000"/>
      <origin rpy="0.00000 0.00000 0.00000" xyz="0.00000 -0.00000 0.00000"/>
      <mass value="0.00000"/>
    </inertial>
    <visual name="LFinger12_link_collision">
      <origin rpy="-0.00000 0.00000 0.00000" xyz="-0.00000 -0.00000 -0.00000"/>
      <material name="phobos_collision"/>
      <geometry>
        <mesh filename="../meshes/stl/LFinger12_0.10.stl" scale="0.10000 0.10000 0.10000"/>
      </geometry>
    </visual>
  </link>
  <link name="LFinger13_link">
    <collision name="LFinger13_link_collision_collision">
      <origin rpy="-0.00000 0.00000 -0.00000" xyz="0.00779 -0.00019 -0.00044"/>
      <geometry>
        <box size="0.01973 0.01591 0.01120"/>
      </geometry>
    </collision>
    <inertial>
      <inertia ixx="0.00000" ixy="0.00000" ixz="0.00000" iyy="0.00000" iyz="0.00000" izz="0.00000"/>
      <origin rpy="0.00000 0.00000 0.00000" xyz="0.00000 0.00000 0.00000"/>
      <mass value="0.00000"/>
    </inertial>
    <visual name="LFinger13_link_collision">
      <origin rpy="-0.00000 -0.00000 0.00000" xyz="0.00000 -0.00000 0.00000"/>
      <material name="phobos_collision"/>
      <geometry>
        <mesh filename="../meshes/stl/LFinger13_0.10.stl" scale="0.10000 0.10000 0.10000"/>
      </geometry>
    </visual>
  </link>
  <link name="LFinger21_link">
    <collision name="LFinger21_link_collision_collision">
      <origin rpy="0.00000 0.00000 0.00000" xyz="0.00800 0.00015 -0.00009"/>
      <geometry>
        <box size="0.01954 0.01599 0.01211"/>
      </geometry>
    </collision>
    <inertial>
      <inertia ixx="0.00000" ixy="0.00000" ixz="0.00000" iyy="0.00000" iyz="-0.00000" izz="0.00000"/>
      <origin rpy="0.00000 0.00000 0.00000" xyz="0.00000 0.00000 0.00000"/>
      <mass value="0.00000"/>
    </inertial>
    <visual name="LFinger21_link_collision">
      <origin rpy="-0.00000 -0.00000 0.00000" xyz="0.00000 -0.00000 -0.00000"/>
      <material name="phobos_collision"/>
      <geometry>
        <mesh filename="../meshes/stl/LFinger21_0.10.stl" scale="0.10000 0.10000 0.10000"/>
      </geometry>
    </visual>
  </link>
  <link name="LFinger22_link">
    <collision name="LFinger22_link_collision_collision">
      <origin rpy="-0.00000 0.00000 0.00000" xyz="0.00774 0.00008 -0.00006"/>
      <geometry>
        <box size="0.01954 0.01599 0.01211"/>
      </geometry>
    </collision>
    <inertial>
      <inertia ixx="0.00000" ixy="0.00000" ixz="0.00000" iyy="0.00000" iyz="0.00000" izz="0.00000"/>
      <origin rpy="0.00000 0.00000 0.00000" xyz="0.00000 0.00000 0.00000"/>
      <mass value="0.00000"/>
    </inertial>
    <visual name="LFinger22_link_collision">
      <origin rpy="0.00000 0.00000 0.00000" xyz="0.00000 -0.00000 -0.00000"/>
      <material name="phobos_collision"/>
      <geometry>
        <mesh filename="../meshes/stl/LFinger22_0.10.stl" scale="0.10000 0.10000 0.10000"/>
      </geometry>
    </visual>
  </link>
  <link name="LFinger23_link">
    <collision name="LFinger23_link_collision_collision">
      <origin rpy="0.00000 -0.00000 0.00000" xyz="0.00787 -0.00014 0.00024"/>
      <geometry>
        <box size="0.01973 0.01560 0.01069"/>
      </geometry>
    </collision>
    <inertial>
      <inertia ixx="0.00000" ixy="-0.00000" ixz="0.00000" iyy="0.00000" iyz="-0.00000" izz="0.00000"/>
      <origin rpy="0.00000 0.00000 0.00000" xyz="-0.00000 0.00000 -0.00000"/>
      <mass value="0.00000"/>
    </inertial>
    <visual name="LFinger23_link_collision">
      <origin rpy="0.00000 -0.00000 0.00000" xyz="-0.00000 -0.00000 -0.00000"/>
      <material name="phobos_collision"/>
      <geometry>
        <mesh filename="../meshes/stl/LFinger23_0.10.stl" scale="0.10000 0.10000 0.10000"/>
      </geometry>
    </visual>
  </link>
  <link name="LFootBumperLeft_frame"/>
  <link name="LFootBumperRight_frame"/>
  <link name="LForeArm">
    <collision name="LForeArm_collision_collision">
      <origin rpy="0.00000 0.00000 -0.06981" xyz="0.02046 0.00144 0.00293"/>
      <geometry>
        <box size="0.07212 0.04968 0.05141"/>
      </geometry>
    </collision>
    <inertial>
      <inertia ixx="0.00002" ixy="0.00000" ixz="0.00000" iyy="0.00004" iyz="0.00000" izz="0.00004"/>
      <origin rpy="0.00000 0.00000 0.00000" xyz="0.02556 0.00281 0.00076"/>
      <mass value="0.07761"/>
    </inertial>
    <visual name="LForeArm_collision">
      <origin rpy="0.00000 0.00000 -0.03491" xyz="0.00000 0.00000 0.00000"/>
      <material name="phobos_collision"/>
      <geometry>
        <mesh filename="../meshes/stl/LElbowRoll_0.10.stl" scale="0.10000 0.10000 0.10000"/>
      </geometry>
    </visual>
  </link>
  <link name="LFsrFL_frame">
    <collision name="LFsrFL_frame_collision_collision">
      <origin rpy="0.00000 0.00000 0.00000" xyz="0.00000 0.00000 0.00000"/>
      <geometry>
        <box size="0.01000 0.01000 0.00500"/>
      </geometry>
    </collision>
    <inertial>
      <inertia ixx="0.00000" ixy="0.00000" ixz="0.00000" iyy="0.00000" iyz="0.00000" izz="0.00000"/>
      <origin rpy="0.00000 0.00000 0.00000" xyz="0.00000 0.00000 0.00000"/>
      <mass value="0.00000"/>
    </inertial>
    <visual name="LFsrFL_frame_collision">
      <origin rpy="0.00000 0.00000 0.00000" xyz="0.00000 0.00000 0.00000"/>
      <material name="phobos_collision"/>
      <geometry>
        <box size="0.01000 0.01000 0.00500"/>
      </geometry>
    </visual>
  </link>
  <link name="LFsrFR_frame">
    <collision name="LFsrFR_frame_collision_collision">
      <origin rpy="0.00000 0.00000 0.00000" xyz="0.00000 0.00000 0.00000"/>
      <geometry>
        <box size="0.01000 0.01000 0.00500"/>
      </geometry>
    </collision>
    <inertial>
      <inertia ixx="0.00000" ixy="0.00000" ixz="0.00000" iyy="0.00000" iyz="0.00000" izz="0.00000"/>
      <origin rpy="0.00000 0.00000 0.00000" xyz="0.00000 0.00000 0.00000"/>
      <mass value="0.00000"/>
    </inertial>
    <visual name="LFsrFR_frame_collision">
      <origin rpy="0.00000 0.00000 0.00000" xyz="0.00000 0.00000 0.00000"/>
      <material name="phobos_collision"/>
      <geometry>
        <box size="0.01000 0.01000 0.00500"/>
      </geometry>
    </visual>
  </link>
  <link name="LFsrRL_frame">
    <collision name="LFsrRL_frame_collision_collision">
      <origin rpy="0.00000 0.00000 0.00000" xyz="0.00000 0.00000 0.00000"/>
      <geometry>
        <box size="0.01000 0.01000 0.00500"/>
      </geometry>
    </collision>
    <inertial>
      <inertia ixx="0.00000" ixy="0.00000" ixz="0.00000" iyy="0.00000" iyz="0.00000" izz="0.00000"/>
      <origin rpy="0.00000 0.00000 0.00000" xyz="0.00000 0.00000 0.00000"/>
      <mass value="0.00000"/>
    </inertial>
    <visual name="LFsrRL_frame_collision">
      <origin rpy="0.00000 0.00000 0.00000" xyz="0.00000 0.00000 0.00000"/>
      <material name="phobos_collision"/>
      <geometry>
        <box size="0.01000 0.01000 0.00500"/>
      </geometry>
    </visual>
  </link>
  <link name="LFsrRR_frame">
    <collision name="LFsrRR_frame_collision_collision">
      <origin rpy="0.00000 0.00000 0.00000" xyz="0.00000 0.00000 0.00000"/>
      <geometry>
        <box size="0.01000 0.01000 0.00500"/>
      </geometry>
    </collision>
    <inertial>
      <inertia ixx="0.00000" ixy="0.00000" ixz="0.00000" iyy="0.00000" iyz="0.00000" izz="0.00000"/>
      <origin rpy="0.00000 0.00000 0.00000" xyz="0.00000 0.00000 0.00000"/>
      <mass value="0.00000"/>
    </inertial>
    <visual name="LFsrRR_frame_collision">
      <origin rpy="0.00000 0.00000 0.00000" xyz="0.00000 0.00000 0.00000"/>
      <material name="phobos_collision"/>
      <geometry>
        <box size="0.01000 0.01000 0.00500"/>
      </geometry>
    </visual>
  </link>
  <link name="LHandTouchBack_frame"/>
  <link name="LHandTouchLeft_frame"/>
  <link name="LHandTouchRight_frame"/>
  <link name="LHip">
    <collision name="LHip_collision_collision">
      <origin rpy="0.00000 0.00000 0.00000" xyz="-0.01140 -0.00242 -0.00719"/>
      <geometry>
        <box size="0.06259 0.03403 0.05367"/>
      </geometry>
    </collision>
    <inertial>
      <inertia ixx="0.00002" ixy="-0.00000" ixz="0.00001" iyy="0.00006" iyz="-0.00000" izz="0.00006"/>
      <origin rpy="0.00000 0.00000 0.00000" xyz="-0.01549 0.00029 -0.00515"/>
      <mass value="0.13053"/>
    </inertial>
    <visual name="LHip_collision">
      <origin rpy="0.00000 0.00000 0.00000" xyz="0.00000 0.00000 0.00000"/>
      <material name="phobos_collision"/>
      <geometry>
        <mesh filename="../meshes/stl/LHipRoll_0.10.stl" scale="0.10000 0.10000 0.10000"/>
      </geometry>
    </visual>
  </link>
  <link name="LInfraRed_frame"/>
  <link name="LPelvis">
    <collision name="LPelvis_collision_collision">
      <origin rpy="0.00000 0.00000 0.00000" xyz="-0.01747 -0.01152 0.01393"/>
      <geometry>
        <box size="0.08280 0.05481 0.05852"/>
      </geometry>
    </collision>
    <inertial>
      <inertia ixx="0.00002" ixy="0.00000" ixz="-0.00000" iyy="0.00005" iyz="0.00000" izz="0.00005"/>
      <origin rpy="0.00000 0.00000 0.00000" xyz="-0.00781 -0.01114 0.02661"/>
      <mass value="0.06981"/>
    </inertial>
    <visual name="LPelvis_collision">
      <origin rpy="0.00000 0.00000 0.00000" xyz="0.00000 0.00000 0.00000"/>
      <material name="phobos_collision"/>
      <geometry>
        <mesh filename="../meshes/stl/LHipYawPitch_0.10.stl" scale="0.10000 0.10000 0.10000"/>
      </geometry>
    </visual>
  </link>
  <link name="LShoulder">
    <collision name="LShoulder_collision_collision">
      <origin rpy="0.00000 0.00000 0.00000" xyz="0.00047 -0.01370 -0.00011"/>
      <geometry>
        <box size="0.06800 0.02418 0.06628"/>
      </geometry>
    </collision>
    <inertial>
      <inertia ixx="0.00003" ixy="0.00000" ixz="0.00000" iyy="0.00001" iyz="-0.00000" izz="0.00003"/>
      <origin rpy="0.00000 0.00000 0.00000" xyz="-0.00165 -0.02663 0.00014"/>
      <mass value="0.07504"/>
    </inertial>
    <visual name="LShoulder_collision">
      <origin rpy="0.00000 0.00000 0.00000" xyz="0.00000 0.00000 0.00000"/>
      <material name="phobos_collision"/>
      <geometry>
        <mesh filename="../meshes/stl/LShoulderPitch_0.10.stl" scale="0.10000 0.10000 0.10000"/>
      </geometry>
    </visual>
  </link>
  <link name="LSonar_frame"/>
  <link name="LThigh">
    <collision name="LThigh_collision_collision">
      <origin rpy="0.00000 0.00000 0.00000" xyz="0.00309 0.00350 -0.05243"/>
      <geometry>
        <box size="0.09620 0.09013 0.14907"/>
      </geometry>
    </collision>
    <inertial>
      <inertia ixx="0.00051" ixy="0.00000" ixz="0.00006" iyy="0.00047" iyz="-0.00001" izz="0.00030"/>
      <origin rpy="0.00000 0.00000 0.00000" xyz="0.00138 0.00221 -0.05373"/>
      <mass value="0.38968"/>
    </inertial>
    <visual name="LThigh_collision">
      <origin rpy="0.00000 0.00000 0.00000" xyz="0.00000 0.00000 0.00000"/>
      <material name="phobos_collision"/>
      <geometry>
        <mesh filename="../meshes/stl/LHipPitch_0.10.stl" scale="0.10000 0.10000 0.10000"/>
      </geometry>
    </visual>
  </link>
  <link name="LThumb1_link">
    <collision name="LThumb1_link_collision_collision">
      <origin rpy="-0.00000 -0.00000 -0.00000" xyz="0.00476 -0.00002 -0.00524"/>
      <geometry>
        <box size="0.01350 0.01539 0.02155"/>
      </geometry>
    </collision>
    <inertial>
      <inertia ixx="0.00000" ixy="-0.00000" ixz="0.00000" iyy="0.00000" iyz="0.00000" izz="0.00000"/>
      <origin rpy="0.00000 0.00000 0.00000" xyz="0.00000 -0.00000 0.00000"/>
      <mass value="0.00000"/>
    </inertial>
    <visual name="LThumb1_link_collision">
      <origin rpy="-0.00000 -0.00000 -0.00000" xyz="-0.00000 -0.00000 -0.00000"/>
      <material name="phobos_collision"/>
      <geometry>
        <mesh filename="../meshes/stl/LThumb1_0.10.stl" scale="0.10000 0.10000 0.10000"/>
      </geometry>
    </visual>
  </link>
  <link name="LThumb2_link">
    <collision name="LThumb2_link_collision_collision">
      <origin rpy="-0.00000 -0.00000 0.00000" xyz="0.00232 -0.00030 -0.00789"/>
      <geometry>
        <box size="0.01419 0.01579 0.02066"/>
      </geometry>
    </collision>
    <inertial>
      <inertia ixx="0.00000" ixy="0.00000" ixz="0.00000" iyy="0.00000" iyz="-0.00000" izz="0.00000"/>
      <origin rpy="0.00000 0.00000 0.00000" xyz="0.00000 0.00000 0.00000"/>
      <mass value="0.00000"/>
    </inertial>
    <visual name="LThumb2_link_collision">
      <origin rpy="-0.00000 0.00000 0.00000" xyz="0.00000 0.00000 0.00000"/>
      <material name="phobos_collision"/>
      <geometry>
        <mesh filename="../meshes/stl/LThumb2_0.10.stl" scale="0.10000 0.10000 0.10000"/>
      </geometry>
    </visual>
  </link>
  <link name="LTibia">
    <collision name="LTibia_collision_collision">
      <origin rpy="0.00000 0.00000 0.00000" xyz="0.00656 0.00539 -0.05048"/>
      <geometry>
        <box size="0.09121 0.09182 0.15120"/>
      </geometry>
    </collision>
    <inertial>
      <inertia ixx="0.00047" ixy="0.00000" ixz="-0.00003" iyy="0.00041" iyz="0.00001" izz="0.00019"/>
      <origin rpy="0.00000 0.00000 0.00000" xyz="0.00453 0.00225 -0.04936"/>
      <mass value="0.29142"/>
    </inertial>
    <visual name="LTibia_collision">
      <origin rpy="0.00000 0.00000 0.00000" xyz="0.00000 0.00000 0.00000"/>
      <material name="phobos_collision"/>
      <geometry>
        <mesh filename="../meshes/stl/LKneePitch_0.10.stl" scale="0.10000 0.10000 0.10000"/>
      </geometry>
    </visual>
  </link>
  <link name="MicroFrontCenter_frame"/>
  <link name="MicroRearCenter_frame"/>
  <link name="MicroSurroundLeft_frame"/>
  <link name="MicroSurroundRight_frame"/>
  <link name="Neck">
    <collision name="Neck_collision_collision">
      <origin rpy="0.00000 0.00000 0.00000" xyz="0.00000 -0.00000 0.00012"/>
      <geometry>
        <box size="0.02520 0.02520 0.02520"/>
      </geometry>
    </collision>
    <inertial>
      <inertia ixx="0.00003" ixy="0.00000" ixz="0.00000" iyy="0.00003" iyz="-0.00000" izz="0.00001"/>
      <origin rpy="0.00000 0.00000 0.00000" xyz="-0.00001 0.00000 -0.02742"/>
      <mass value="0.06442"/>
    </inertial>
    <visual name="Neck_collision">
      <origin rpy="0.00000 0.00000 0.00000" xyz="0.00000 0.00000 0.00000"/>
      <material name="phobos_collision"/>
      <geometry>
        <mesh filename="../meshes/stl/HeadYaw_0.10.stl" scale="0.10000 0.10000 0.10000"/>
      </geometry>
    </visual>
  </link>
  <link name="RAnklePitch">
    <collision name="RAnklePitch_collision_collision">
      <origin rpy="0.00000 0.00000 0.00000" xyz="-0.00040 0.00126 0.01220"/>
      <geometry>
        <box size="0.07404 0.03136 0.06433"/>
      </geometry>
    </collision>
    <inertial>
      <inertia ixx="0.00003" ixy="0.00000" ixz="0.00000" iyy="0.00007" iyz="-0.00000" izz="0.00005"/>
      <origin rpy="0.00000 0.00000 0.00000" xyz="0.00045 -0.00029 0.00685"/>
      <mass value="0.13416"/>
    </inertial>
    <visual name="RAnklePitch_collision">
      <origin rpy="0.00000 0.00000 0.00000" xyz="0.00000 0.00000 0.00000"/>
      <material name="phobos_collision"/>
      <geometry>
        <mesh filename="../meshes/stl/RAnklePitch_0.10.stl" scale="0.10000 0.10000 0.10000"/>
      </geometry>
    </visual>
  </link>
  <link name="RBicep">
    <collision name="RBicep_collision_collision">
      <origin rpy="0.00000 0.00000 0.00000" xyz="0.03816 -0.00562 -0.00026"/>
      <geometry>
        <box size="0.17183 0.06085 0.08297"/>
      </geometry>
    </collision>
    <inertial>
      <inertia ixx="0.00010" ixy="0.00005" ixz="-0.00001" iyy="0.00027" iyz="0.00001" izz="0.00025"/>
      <origin rpy="0.00000 0.00000 0.00000" xyz="0.02455 -0.00563 0.00330"/>
      <mass value="0.15777"/>
    </inertial>
    <visual name="RBicep_collision">
      <origin rpy="0.00000 0.00000 0.00000" xyz="0.00000 0.00000 0.00000"/>
      <material name="phobos_collision"/>
      <geometry>
        <mesh filename="../meshes/stl/RShoulderRoll_0.10.stl" scale="0.10000 0.10000 0.10000"/>
      </geometry>
    </visual>
  </link>
  <link name="RElbow">
    <inertial>
      <inertia ixx="0.00001" ixy="0.00000" ixz="0.00000" iyy="0.00003" iyz="-0.00000" izz="0.00003"/>
      <origin rpy="0.00000 0.00000 0.00000" xyz="-0.02744 0.00000 -0.00014"/>
      <mass value="0.06483"/>
    </inertial>
  </link>
  <link name="RFinger11_link">
    <collision name="RFinger11_link_collision_collision">
      <origin rpy="-0.00000 0.00000 0.00000" xyz="0.00825 -0.00050 -0.00047"/>
      <geometry>
        <box size="0.01954 0.01567 0.01232"/>
      </geometry>
    </collision>
    <inertial>
      <inertia ixx="0.00000" ixy="0.00000" ixz="-0.00000" iyy="0.00000" iyz="0.00000" izz="0.00000"/>
      <origin rpy="0.00000 0.00000 0.00000" xyz="0.00000 0.00000 0.00000"/>
      <mass value="0.00000"/>
    </inertial>
    <visual name="RFinger11_link_collision">
      <origin rpy="0.00000 0.00000 0.00000" xyz="-0.00000 0.00000 0.00000"/>
      <material name="phobos_collision"/>
      <geometry>
        <mesh filename="../meshes/stl/RFinger11_0.10.stl" scale="0.10000 0.10000 0.10000"/>
      </geometry>
    </visual>
  </link>
  <link name="RFinger12_link">
    <collision name="RFinger12_link_collision_collision">
      <origin rpy="-0.00000 -0.00000 -0.00000" xyz="0.00658 0.00004 -0.00048"/>
      <geometry>
        <box size="0.01954 0.01519 0.01264"/>
      </geometry>
    </collision>
    <inertial>
      <inertia ixx="0.00000" ixy="0.00000" ixz="0.00000" iyy="0.00000" iyz="0.00000" izz="0.00000"/>
      <origin rpy="0.00000 0.00000 0.00000" xyz="0.00000 -0.00000 0.00000"/>
      <mass value="0.00000"/>
    </inertial>
    <visual name="RFinger12_link_collision">
      <origin rpy="0.00000 -0.00000 0.00000" xyz="0.00000 -0.00000 -0.00000"/>
      <material name="phobos_collision"/>
      <geometry>
        <mesh filename="../meshes/stl/RFinger12_0.10.stl" scale="0.10000 0.10000 0.10000"/>
      </geometry>
    </visual>
  </link>
  <link name="RFinger13_link">
    <collision name="RFinger13_link_collision_collision">
      <origin rpy="0.00000 0.00000 0.00000" xyz="0.00755 -0.00029 -0.00043"/>
      <geometry>
        <box size="0.01973 0.01591 0.01120"/>
      </geometry>
    </collision>
    <inertial>
      <inertia ixx="0.00000" ixy="0.00000" ixz="-0.00000" iyy="0.00000" iyz="-0.00000" izz="0.00000"/>
      <origin rpy="0.00000 0.00000 0.00000" xyz="0.00000 -0.00000 -0.00000"/>
      <mass value="0.00000"/>
    </inertial>
    <visual name="RFinger13_link_collision">
      <origin rpy="0.00000 0.00000 0.00000" xyz="0.00000 -0.00000 -0.00000"/>
      <material name="phobos_collision"/>
      <geometry>
        <mesh filename="../meshes/stl/RFinger13_0.10.stl" scale="0.10000 0.10000 0.10000"/>
      </geometry>
    </visual>
  </link>
  <link name="RFinger21_link">
    <collision name="RFinger21_link_collision_collision">
      <origin rpy="-0.00000 -0.00000 -0.00000" xyz="0.00781 0.00003 -0.00054"/>
      <geometry>
        <box size="0.01954 0.01599 0.01211"/>
      </geometry>
    </collision>
    <inertial>
      <inertia ixx="0.00000" ixy="0.00000" ixz="0.00000" iyy="0.00000" iyz="0.00000" izz="0.00000"/>
      <origin rpy="0.00000 0.00000 0.00000" xyz="0.00000 0.00000 0.00000"/>
      <mass value="0.00000"/>
    </inertial>
    <visual name="RFinger21_link_collision">
      <origin rpy="-0.00000 -0.00000 -0.00000" xyz="-0.00000 -0.00000 0.00000"/>
      <material name="phobos_collision"/>
      <geometry>
        <mesh filename="../meshes/stl/RFinger21_0.10.stl" scale="0.10000 0.10000 0.10000"/>
      </geometry>
    </visual>
  </link>
  <link name="RFinger22_link">
    <collision name="RFinger22_link_collision_collision">
      <origin rpy="0.00000 -0.00000 0.00000" xyz="0.00765 -0.00065 -0.00017"/>
      <geometry>
        <box size="0.01954 0.01599 0.01211"/>
      </geometry>
    </collision>
    <inertial>
      <inertia ixx="0.00000" ixy="-0.00000" ixz="0.00000" iyy="0.00000" iyz="0.00000" izz="0.00000"/>
      <origin rpy="0.00000 0.00000 0.00000" xyz="0.00000 -0.00000 0.00000"/>
      <mass value="0.00000"/>
    </inertial>
    <visual name="RFinger22_link_collision">
      <origin rpy="0.00000 -0.00000 0.00000" xyz="0.00000 0.00000 -0.00000"/>
      <material name="phobos_collision"/>
      <geometry>
        <mesh filename="../meshes/stl/RFinger22_0.10.stl" scale="0.10000 0.10000 0.10000"/>
      </geometry>
    </visual>
  </link>
  <link name="RFinger23_link">
    <collision name="RFinger23_link_collision_collision">
      <origin rpy="-0.00000 -0.00000 -0.00000" xyz="0.00783 -0.00038 -0.00003"/>
      <geometry>
        <box size="0.01973 0.01577 0.01118"/>
      </geometry>
    </collision>
    <inertial>
      <inertia ixx="0.00000" ixy="0.00000" ixz="-0.00000" iyy="0.00000" iyz="0.00000" izz="0.00000"/>
      <origin rpy="0.00000 0.00000 0.00000" xyz="-0.00000 0.00000 0.00000"/>
      <mass value="0.00000"/>
    </inertial>
    <visual name="RFinger23_link_collision">
      <origin rpy="-0.00000 0.00000 -0.00000" xyz="0.00000 0.00000 0.00000"/>
      <material name="phobos_collision"/>
      <geometry>
        <mesh filename="../meshes/stl/RFinger23_0.10.stl" scale="0.10000 0.10000 0.10000"/>
      </geometry>
    </visual>
  </link>
  <link name="RFootBumperLeft_frame"/>
  <link name="RFootBumperRight_frame"/>
  <link name="RForeArm">
    <collision name="RForeArm_collision_collision">
      <origin rpy="0.00000 0.00000 0.06981" xyz="0.02122 -0.00177 0.00246"/>
      <geometry>
        <box size="0.07235 0.04878 0.05006"/>
      </geometry>
    </collision>
    <inertial>
      <inertia ixx="0.00002" ixy="-0.00000" ixz="0.00000" iyy="0.00004" iyz="-0.00000" izz="0.00004"/>
      <origin rpy="0.00000 0.00000 0.00000" xyz="0.02556 -0.00281 0.00076"/>
      <mass value="0.07761"/>
    </inertial>
    <visual name="RForeArm_collision">
      <origin rpy="0.00000 0.00000 0.03491" xyz="0.00000 0.00000 0.00000"/>
      <material name="phobos_collision"/>
      <geometry>
        <mesh filename="../meshes/stl/RElbowRoll_0.10.stl" scale="0.10000 0.10000 0.10000"/>
      </geometry>
    </visual>
  </link>
  <link name="RFsrFL_frame">
    <collision name="RFsrFL_frame_collision_collision">
      <origin rpy="0.00000 0.00000 0.00000" xyz="0.00000 0.00000 0.00000"/>
      <geometry>
        <box size="0.01000 0.01000 0.00500"/>
      </geometry>
    </collision>
    <inertial>
      <inertia ixx="0.00000" ixy="0.00000" ixz="0.00000" iyy="0.00000" iyz="0.00000" izz="0.00000"/>
      <origin rpy="0.00000 0.00000 0.00000" xyz="0.00000 0.00000 0.00000"/>
      <mass value="0.00000"/>
    </inertial>
    <visual name="RFsrFL_frame_collision">
      <origin rpy="0.00000 0.00000 0.00000" xyz="0.00000 0.00000 0.00000"/>
      <material name="phobos_collision"/>
      <geometry>
        <box size="0.01000 0.01000 0.00500"/>
      </geometry>
    </visual>
  </link>
  <link name="RFsrFR_frame">
    <collision name="RFsrFR_frame_collision_collision">
      <origin rpy="0.00000 0.00000 0.00000" xyz="0.00000 0.00000 0.00000"/>
      <geometry>
        <box size="0.01000 0.01000 0.00500"/>
      </geometry>
    </collision>
    <inertial>
      <inertia ixx="0.00000" ixy="0.00000" ixz="0.00000" iyy="0.00000" iyz="0.00000" izz="0.00000"/>
      <origin rpy="0.00000 0.00000 0.00000" xyz="0.00000 0.00000 0.00000"/>
      <mass value="0.00000"/>
    </inertial>
    <visual name="RFsrFR_frame_collision">
      <origin rpy="0.00000 0.00000 0.00000" xyz="0.00000 0.00000 0.00000"/>
      <material name="phobos_collision"/>
      <geometry>
        <box size="0.01000 0.01000 0.00500"/>
      </geometry>
    </visual>
  </link>
  <link name="RFsrRL_frame">
    <collision name="RFsrRL_frame_collision_collision">
      <origin rpy="0.00000 0.00000 0.00000" xyz="0.00000 0.00000 0.00000"/>
      <geometry>
        <box size="0.01000 0.01000 0.00500"/>
      </geometry>
    </collision>
    <inertial>
      <inertia ixx="0.00000" ixy="0.00000" ixz="0.00000" iyy="0.00000" iyz="0.00000" izz="0.00000"/>
      <origin rpy="0.00000 0.00000 0.00000" xyz="0.00000 0.00000 0.00000"/>
      <mass value="0.00000"/>
    </inertial>
    <visual name="RFsrRL_frame_collision">
      <origin rpy="0.00000 0.00000 0.00000" xyz="0.00000 0.00000 0.00000"/>
      <material name="phobos_collision"/>
      <geometry>
        <box size="0.01000 0.01000 0.00500"/>
      </geometry>
    </visual>
  </link>
  <link name="RFsrRR_frame">
    <collision name="RFsrRR_frame_collision_collision">
      <origin rpy="0.00000 0.00000 0.00000" xyz="0.00000 0.00000 0.00000"/>
      <geometry>
        <box size="0.01000 0.01000 0.00500"/>
      </geometry>
    </collision>
    <inertial>
      <inertia ixx="0.00000" ixy="0.00000" ixz="0.00000" iyy="0.00000" iyz="0.00000" izz="0.00000"/>
      <origin rpy="0.00000 0.00000 0.00000" xyz="0.00000 0.00000 0.00000"/>
      <mass value="0.00000"/>
    </inertial>
    <visual name="RFsrRR_frame_collision">
      <origin rpy="0.00000 0.00000 0.00000" xyz="0.00000 0.00000 0.00000"/>
      <material name="phobos_collision"/>
      <geometry>
        <box size="0.01000 0.01000 0.00500"/>
      </geometry>
    </visual>
  </link>
  <link name="RHandTouchBack_frame"/>
  <link name="RHandTouchLeft_frame"/>
  <link name="RHandTouchRight_frame"/>
  <link name="RHip">
    <collision name="RHip_collision_collision">
      <origin rpy="0.00000 0.00000 0.00000" xyz="-0.01140 0.00242 -0.00719"/>
      <geometry>
        <box size="0.06259 0.03403 0.05367"/>
      </geometry>
    </collision>
    <inertial>
      <inertia ixx="0.00002" ixy="0.00000" ixz="0.00001" iyy="0.00006" iyz="0.00000" izz="0.00006"/>
      <origin rpy="0.00000 0.00000 0.00000" xyz="-0.01549 -0.00029 -0.00515"/>
      <mass value="0.13053"/>
    </inertial>
    <visual name="RHip_collision">
      <origin rpy="0.00000 0.00000 0.00000" xyz="0.00000 0.00000 0.00000"/>
      <material name="phobos_collision"/>
      <geometry>
        <mesh filename="../meshes/stl/RHipRoll_0.10.stl" scale="0.10000 0.10000 0.10000"/>
      </geometry>
    </visual>
  </link>
  <link name="RInfraRed_frame"/>
  <link name="RPelvis">
    <collision name="RPelvis_collision_collision">
      <origin rpy="0.00000 0.00000 0.00000" xyz="-0.01747 0.01196 0.01359"/>
      <geometry>
        <box size="0.08280 0.05568 0.05907"/>
      </geometry>
    </collision>
    <inertial>
      <inertia ixx="0.00003" ixy="-0.00000" ixz="-0.00000" iyy="0.00005" iyz="-0.00001" izz="0.00005"/>
      <origin rpy="0.00000 0.00000 0.00000" xyz="-0.00781 0.01114 0.02661"/>
      <mass value="0.06981"/>
    </inertial>
    <visual name="RPelvis_collision">
      <origin rpy="0.00000 0.00000 0.00000" xyz="0.00000 0.00000 0.00000"/>
      <material name="phobos_collision"/>
      <geometry>
        <mesh filename="../meshes/stl/RHipYawPitch_0.10.stl" scale="0.10000 0.10000 0.10000"/>
      </geometry>
    </visual>
  </link>
  <link name="RShoulder">
    <collision name="RShoulder_collision_collision">
      <origin rpy="0.00000 0.00000 0.00000" xyz="0.00093 0.01359 -0.00050"/>
      <geometry>
        <box size="0.06892 0.02440 0.06750"/>
      </geometry>
    </collision>
    <inertial>
      <inertia ixx="0.00003" ixy="-0.00000" ixz="0.00000" iyy="0.00001" iyz="0.00000" izz="0.00003"/>
      <origin rpy="0.00000 0.00000 0.00000" xyz="-0.00165 0.02663 0.00014"/>
      <mass value="0.07504"/>
    </inertial>
    <visual name="RShoulder_collision">
      <origin rpy="0.00000 0.00000 0.00000" xyz="0.00000 0.00000 0.00000"/>
      <material name="phobos_collision"/>
      <geometry>
        <mesh filename="../meshes/stl/RShoulderPitch_0.10.stl" scale="0.10000 0.10000 0.10000"/>
      </geometry>
    </visual>
  </link>
  <link name="RSonar_frame"/>
  <link name="RThigh">
    <collision name="RThigh_collision_collision">
      <origin rpy="0.00000 0.00000 0.00000" xyz="0.00309 -0.00350 -0.05210"/>
      <geometry>
        <box size="0.09620 0.09013 0.14906"/>
      </geometry>
    </collision>
    <inertial>
      <inertia ixx="0.00051" ixy="-0.00000" ixz="0.00006" iyy="0.00047" iyz="0.00001" izz="0.00030"/>
      <origin rpy="0.00000 0.00000 0.00000" xyz="0.00138 -0.00221 -0.05373"/>
      <mass value="0.38968"/>
    </inertial>
    <visual name="RThigh_collision">
      <origin rpy="0.00000 0.00000 0.00000" xyz="0.00000 0.00000 0.00000"/>
      <material name="phobos_collision"/>
      <geometry>
        <mesh filename="../meshes/stl/RHipPitch_0.10.stl" scale="0.10000 0.10000 0.10000"/>
      </geometry>
    </visual>
  </link>
  <link name="RThumb1_link">
    <collision name="RThumb1_link_collision_collision">
      <origin rpy="0.00000 0.00000 -0.00000" xyz="0.00583 0.00034 -0.00487"/>
      <geometry>
        <box size="0.01350 0.01539 0.02155"/>
      </geometry>
    </collision>
    <inertial>
      <inertia ixx="0.00000" ixy="-0.00000" ixz="-0.00000" iyy="0.00000" iyz="-0.00000" izz="0.00000"/>
      <origin rpy="0.00000 0.00000 0.00000" xyz="0.00000 0.00000 0.00000"/>
      <mass value="0.00000"/>
    </inertial>
    <visual name="RThumb1_link_collision">
      <origin rpy="0.00000 0.00000 -0.00000" xyz="-0.00000 -0.00000 0.00000"/>
      <material name="phobos_collision"/>
      <geometry>
        <mesh filename="../meshes/stl/RThumb1_0.10.stl" scale="0.10000 0.10000 0.10000"/>
      </geometry>
    </visual>
  </link>
  <link name="RThumb2_link">
    <collision name="RThumb2_link_collision_collision">
      <origin rpy="-0.00000 0.00000 -0.00000" xyz="0.00268 -0.00003 -0.00703"/>
      <geometry>
        <box size="0.01402 0.01579 0.02056"/>
      </geometry>
    </collision>
    <inertial>
      <inertia ixx="0.00000" ixy="0.00000" ixz="-0.00000" iyy="0.00000" iyz="-0.00000" izz="0.00000"/>
      <origin rpy="0.00000 0.00000 0.00000" xyz="0.00000 0.00000 0.00000"/>
      <mass value="0.00000"/>
    </inertial>
    <visual name="RThumb2_link_collision">
      <origin rpy="0.00000 -0.00000 -0.00000" xyz="0.00000 0.00000 -0.00000"/>
      <material name="phobos_collision"/>
      <geometry>
        <mesh filename="../meshes/stl/RThumb2_0.10.stl" scale="0.10000 0.10000 0.10000"/>
      </geometry>
    </visual>
  </link>
  <link name="RTibia">
    <collision name="RTibia_collision_collision">
      <origin rpy="0.00000 0.00000 0.00000" xyz="0.00656 -0.00557 -0.05173"/>
      <geometry>
        <box size="0.09121 0.09117 0.14870"/>
      </geometry>
    </collision>
    <inertial>
      <inertia ixx="0.00047" ixy="-0.00000" ixz="-0.00004" iyy="0.00041" iyz="-0.00001" izz="0.00018"/>
      <origin rpy="0.00000 0.00000 0.00000" xyz="0.00453 -0.00225 -0.04936"/>
      <mass value="0.29142"/>
    </inertial>
    <visual name="RTibia_collision">
      <origin rpy="0.00000 0.00000 0.00000" xyz="0.00000 0.00000 0.00000"/>
      <material name="phobos_collision"/>
      <geometry>
        <mesh filename="../meshes/stl/RKneePitch_0.10.stl" scale="0.10000 0.10000 0.10000"/>
      </geometry>
    </visual>
  </link>
  <link name="base_link"/>
  <link name="gaze"/>
  <link name="l_ankle">
    <collision name="l_ankle_collision_collision">
      <origin rpy="0.00000 0.00000 0.00000" xyz="0.02121 0.00649 -0.01301"/>
      <geometry>
        <box size="0.16386 0.09221 0.06587"/>
      </geometry>
    </collision>
    <inertial>
      <inertia ixx="0.00010" ixy="0.00001" ixz="0.00001" iyy="0.00037" iyz="0.00000" izz="0.00042"/>
      <origin rpy="0.00000 0.00000 0.00000" xyz="0.02542 0.00330 -0.03239"/>
      <mass value="0.16184"/>
    </inertial>
    <visual name="l_ankle_collision">
      <origin rpy="0.00000 0.00000 0.00000" xyz="0.00000 0.00000 0.00000"/>
      <material name="phobos_collision"/>
      <geometry>
        <mesh filename="../meshes/stl/LAnkleRoll_0.10.stl" scale="0.10000 0.10000 0.10000"/>
      </geometry>
    </visual>
  </link>
  <link name="l_gripper">
    <inertial>
      <inertia ixx="0.00000" ixy="0.00000" ixz="0.00000" iyy="0.00000" iyz="0.00000" izz="0.00000"/>
      <origin rpy="0.00000 0.00000 0.00000" xyz="0.00000 0.00000 0.00000"/>
      <mass value="0.00000"/>
    </inertial>
  </link>
  <link name="l_sole"/>
  <link name="l_wrist">
    <collision name="l_wrist_collision_collision">
      <origin rpy="0.00000 0.00000 0.00000" xyz="0.04250 0.00002 -0.00016"/>
      <geometry>
        <box size="0.08481 0.06829 0.06300"/>
      </geometry>
    </collision>
    <inertial>
      <inertia ixx="0.00007" ixy="0.00000" ixz="-0.00000" iyy="0.00014" iyz="0.00000" izz="0.00013"/>
      <origin rpy="0.00000 0.00000 0.00000" xyz="0.03434 -0.00088 0.00308"/>
      <mass value="0.18533"/>
    </inertial>
    <visual name="l_wrist_collision">
      <origin rpy="0.00000 0.00000 0.00000" xyz="0.00000 0.00000 0.00000"/>
      <material name="phobos_collision"/>
      <geometry>
        <mesh filename="../meshes/stl/LWristYaw_0.10.stl" scale="0.10000 0.10000 0.10000"/>
      </geometry>
    </visual>
  </link>
  <link name="r_ankle">
    <collision name="r_ankle_collision_collision">
      <origin rpy="0.00000 0.00000 0.00000" xyz="0.02130 -0.00644 -0.01301"/>
      <geometry>
        <box size="0.16405 0.09226 0.06588"/>
      </geometry>
    </collision>
    <inertial>
      <inertia ixx="0.00010" ixy="-0.00001" ixz="0.00001" iyy="0.00037" iyz="-0.00000" izz="0.00042"/>
      <origin rpy="0.00000 0.00000 0.00000" xyz="0.02542 -0.00330 -0.03239"/>
      <mass value="0.16184"/>
    </inertial>
    <visual name="r_ankle_collision">
      <origin rpy="0.00000 0.00000 0.00000" xyz="0.00000 0.00000 0.00000"/>
      <material name="phobos_collision"/>
      <geometry>
        <mesh filename="../meshes/stl/RAnkleRoll_0.10.stl" scale="0.10000 0.10000 0.10000"/>
      </geometry>
    </visual>
  </link>
  <link name="r_gripper">
    <inertial>
      <inertia ixx="0.00000" ixy="0.00000" ixz="0.00000" iyy="0.00000" iyz="0.00000" izz="0.00000"/>
      <origin rpy="0.00000 0.00000 0.00000" xyz="0.00000 0.00000 0.00000"/>
      <mass value="0.00000"/>
    </inertial>
  </link>
  <link name="r_sole"/>
  <link name="r_wrist">
    <collision name="r_wrist_collision_collision">
      <origin rpy="0.00000 0.00000 -0.00000" xyz="0.04244 0.00002 -0.00043"/>
      <geometry>
        <box size="0.08469 0.06800 0.06321"/>
      </geometry>
    </collision>
    <inertial>
      <inertia ixx="0.00007" ixy="0.00001" ixz="-0.00000" iyy="0.00014" iyz="0.00000" izz="0.00013"/>
      <origin rpy="0.00000 0.00000 0.00000" xyz="0.03434 0.00088 0.00308"/>
      <mass value="0.18533"/>
    </inertial>
    <visual name="r_wrist_collision">
      <origin rpy="0.00000 0.00000 -0.00000" xyz="0.00000 0.00000 0.00000"/>
      <material name="phobos_collision"/>
      <geometry>
        <mesh filename="../meshes/stl/RWristYaw_0.10.stl" scale="0.10000 0.10000 0.10000"/>
      </geometry>
    </visual>
  </link>
  <link name="torso">
    <collision name="torso_collision_collision">
      <origin rpy="0.00000 0.00000 0.00000" xyz="0.00334 -0.00000 0.01958"/>
      <geometry>
        <box size="0.11168 0.17400 0.23094"/>
      </geometry>
    </collision>
    <inertial>
      <inertia ixx="0.00308" ixy="0.00001" ixz="-0.00003" iyy="0.00288" iyz="-0.00003" izz="0.00159"/>
      <origin rpy="0.00000 0.00000 0.00000" xyz="-0.00413 0.00000 0.04342"/>
      <mass value="1.04956"/>
    </inertial>
    <visual name="torso_collision">
      <origin rpy="0.00000 0.00000 0.00000" xyz="0.00000 0.00000 0.00000"/>
      <material name="phobos_collision"/>
      <geometry>
        <mesh filename="../meshes/stl/Torso_0.10.stl" scale="0.10000 0.10000 0.10000"/>
      </geometry>
    </visual>
  </link>
  <material name="phobos_collision">
    <color rgba="0.80000 0.49804 0.00000 0.20000"/>
  </material>
</robot>